<mujoco model="WildRobotDev">
  <option>
    <flag eulerdamp="disable" />
  </option>
  <compiler angle="radian" meshdir="assets" autolimits="true" />
  <default>
    <default class="WildRobotDev">
      <joint frictionloss="0.1" armature="0.005" />
      <position kp="50" dampratio="1" />
      <default class="visual">
        <geom type="mesh" contype="0" conaffinity="0" group="2" />
      </default>
      <default class="collision">
        <geom group="3" type="sphere" />
      </default>
    </default>
    <default class="htd45hServo">
      <geom contype="0" conaffinity="0" />
      <joint damping="0.08516" frictionloss="0.022275" armature="0.024992" />
      <position kp="21.1" kv="0.5" forcerange="-4.0 4.0" />
    </default>
    <default class="backlash">
      <joint damping="0.01" frictionloss="0" armature="0.01" limited="true" range="-0.008726646259971648 0.008726646259971648" />
    </default>
  </default>
  <sensor>
    <gyro site="chest_imu" name="chest_imu_gyro" noise="0.0002" cutoff="100" />
    <accelerometer site="chest_imu" name="chest_imu_accel" noise="0.0015" cutoff="100" />
    <magnetometer site="chest_imu" name="chest_imu_mag" noise="0.3" />
    <framequat objtype="site" objname="chest_imu" name="chest_imu_quat" />
    <velocimeter site="pelvis_mimic" name="pelvis_local_linvel" />
  </sensor>
  <worldbody>
    <body name="waist" pos="0 0 0.5" quat="1 0 0 0" childclass="WildRobotDev">
      <freejoint name="waist_freejoint" />
      <inertial pos="0.00207427 0.00159876 0.0785345" mass="1.28083" fullinertia="0.00602084 0.00549671 0.00162867 -0.000111987 -0.00020739 -0.000103631" />
      <geom type="mesh" class="visual" pos="0.000128558 -0.000153209 0.12518" quat="0.34202 -1.65887e-17 -5.55112e-17 -0.939693" mesh="waist_trunk_support" material="waist_trunk_support_material" />
      <geom type="mesh" class="visual" pos="-1.8982e-19 0 0" quat="0.707107 0 0 -0.707107" mesh="trunk_bottom" material="trunk_bottom_material" />
      <geom type="mesh" class="visual" pos="5.89806e-17 -3.1225e-17 0" quat="0.707107 0 0 -0.707107" mesh="trunk_servo_connect" material="trunk_servo_connect_material" />
      <geom type="mesh" class="visual" pos="1.38778e-17 -0.00025 1.47949e-17" quat="0.707107 0 0 0.707107" mesh="hip_cover" material="hip_cover_material" />
      <geom type="mesh" class="visual" pos="-1.59595e-16 -1.66533e-16 0.12518" quat="0.34202 -5.80156e-17 0 -0.939693" mesh="scroll_out" material="scroll_out_material" />
      <geom type="mesh" class="visual" pos="0.000128558 0.000153209 0.12518" quat="0.939693 -2.94205e-17 -1.35637e-16 -0.34202" mesh="waist_trunk_support" material="waist_trunk_support_material" />
      <geom type="mesh" class="visual" pos="1.38778e-17 -0.0001 1.53661e-17" quat="0.707107 0 1.11022e-16 0.707107" mesh="hip_trunk_connect" material="hip_trunk_connect_material" />
      <geom type="mesh" class="visual" pos="-0.000128558 -0.000153209 0.12518" quat="0.34202 -0 -5.91646e-31 0.939693" mesh="waist_trunk_support" material="waist_trunk_support_material" />
      <geom type="mesh" class="visual" pos="-0.000128558 0.000153209 0.12518" quat="0.939693 0 -0 0.34202" mesh="waist_trunk_support" material="waist_trunk_support_material" />
      <geom type="mesh" class="visual" pos="-1.38778e-17 0.00025 1.46954e-17" quat="0.707107 0 2.22045e-16 -0.707107" mesh="hip_cover" material="hip_cover_material" />
      <geom type="mesh" class="visual" pos="-1.38778e-17 0.0001 1.3452e-17" quat="0.707107 0 1.11022e-16 -0.707107" mesh="hip_trunk_connect" material="hip_trunk_connect_material" />
      <geom type="mesh" class="visual" pos="-0.21121 0.0233777 0.0810344" quat="0.499502 -0.500498 -0.500085 0.499915" mesh="cell" material="cell_material" />
      <geom type="mesh" class="visual" pos="0.031089 0.00995652 0.116228" quat="0.000704463 0.707107 0.707106 0.000120096" mesh="rp_assemble" material="rp_assemble_material" />
      <geom type="mesh" class="visual" pos="0.023299 -4.3479e-05 0.116227" quat="0.707106 0.000120096 -0.000704463 -0.707107" mesh="batterybox" material="batterybox_material" />
      <geom type="mesh" class="visual" pos="-0.23501 -7.2321e-05 0.0810261" quat="0.499502 -0.500498 -0.500085 0.499915" mesh="cell" material="cell_material" />
      <geom type="mesh" class="visual" pos="-0.23501 -0.0235223 0.0810454" quat="0.499502 -0.500498 -0.500085 0.499915" mesh="cell" material="cell_material" />
      <geom type="mesh" class="visual" pos="-0.000210713 -3.65539e-05 0.124579" quat="0.707107 -0.000704463 -0.000120096 0.707106" mesh="waist_platform" material="waist_platform_material" />
      <geom type="mesh" class="visual" pos="-0.000210713 -3.65539e-05 0.124579" quat="0.707107 -0.000704463 -0.000120096 0.707106" mesh="waist_platform_2" material="waist_platform_2_material" />
      <geom type="mesh" class="visual" pos="-0.23501 0.0233777 0.0810067" quat="0.499502 -0.500498 -0.500085 0.499915" mesh="cell" material="cell_material" />
      <geom type="mesh" class="visual" pos="-0.21121 -0.0235223 0.0810732" quat="0.499502 -0.500498 -0.500085 0.499915" mesh="cell" material="cell_material" />
      <geom type="mesh" class="visual" pos="-0.21121 -7.2321e-05 0.0810538" quat="0.499502 -0.500498 -0.500085 0.499915" mesh="cell" material="cell_material" />
      <site group="3" name="pelvis_mimic" pos="0 0 0" quat="1 0 0 0" />
      <body name="pelvis_mimic" pos="0 0 0" quat="1 0 0 0">
        <inertial pos="0 0 0" mass="0.001" diaginertia="0.000001 0.000001 0.000001" />
      </body>
      <site group="3" name="chest_imu" pos="-0.000260412 0.000259929 0.1672" quat="1 -0.00041321 -0.000583051 -2.40923e-07" />
      <body name="left_hip" pos="-4.74705e-05 0.0536 -0.0335836" quat="0.000292354 -0.000292013 0.707519 -0.706694">
        <joint axis="0 0 1" name="left_hip_pitch" type="hinge" range="-0.08726835630835118 1.5707944330862618" class="htd45hServo" />
        <inertial pos="-0.00291442 -0.00897832 -0.0331054" mass="0.0849728" fullinertia="2.00234e-05 1.92641e-05 2.44282e-05 3.89653e-07 -8.25998e-07 -1.4809e-06" />
        <geom type="mesh" class="visual" pos="-9.99364e-05 -0.03359 0.0566" quat="0.5 0.5 0.5 -0.5" mesh="hip_servo_hook_left" material="hip_servo_hook_left_material" />
        <body name="upper_leg" pos="-0.0269 -0.00016648 -0.0365475" quat="0.707399 -0.000412779 0.706814 0.00041312">
          <joint axis="0 0 1" name="left_hip_roll" type="hinge" range="-1.5707963267948664 0.17453292519946315" class="htd45hServo" />
          <inertial pos="-0.00109676 0.15941 0.0267063" mass="0.236565" fullinertia="0.000988751 0.000126498 0.000981911 1.04431e-05 -1.12408e-08 1.05493e-06" />
          <geom type="mesh" class="visual" pos="-0.095 -4.85723e-17 0.0267" quat="0.707107 0.707107 5.44009e-15 -5.43327e-15" mesh="up_leg_servo_connect" material="up_leg_servo_connect_material" />
          <geom type="mesh" class="visual" pos="-0.095 1.4988e-15 0.0267" quat="0.707107 0.707107 1.35447e-14 -1.34176e-14" mesh="up_leg" material="up_leg_material" />
          <geom type="mesh" class="visual" pos="-0.095 -0.0002 0.0267" quat="0.707107 0.707107 1.36557e-14 -1.33446e-14" mesh="knee_ball_left" material="knee_ball_left_material" />
          <geom type="mesh" class="visual" pos="-0.095 -0.0002 0.0267" quat="0.707107 0.707107 1.36557e-14 -1.34176e-14" mesh="knee_ball_mid" material="knee_ball_mid_material" />
          <geom type="mesh" class="visual" pos="-0.095 -0.0002 0.0267" quat="0.707107 0.707107 1.36557e-14 -1.33446e-14" mesh="knee_ball_right" material="knee_ball_right_material" />
          <site group="3" name="left_knee_mimic" pos="0.000138461 0.192701 0.0266255" quat="0.49875 0.501659 0.498338 -0.501244" />
          <body name="left_knee_mimic" pos="0.000138461 0.192701 0.0266255" quat="0.49875 0.501659 0.498338 -0.501244">
            <inertial pos="0 0 0" mass="0.001" diaginertia="0.000001 0.000001 0.000001" />
          </body>
          <site group="3" name="left_knee_imu" pos="-1.06859e-15 0.173352 0.0264651" quat="0.5 0.5 0.5 -0.5" />
          <body name="lower_leg" pos="-0.02705 0.192552 0.0267" quat="1.63398e-14 -0.707107 1.62093e-14 -0.707107">
            <joint axis="0 0 1" name="left_knee_pitch" type="hinge" range="0.0 1.3962634015954636" class="htd45hServo" />
            <inertial pos="-0.000528282 -0.102749 0.0267516" mass="0.37567" fullinertia="0.00172198 0.000666836 0.0016363 1.91588e-05 9.23751e-08 -2.38646e-05" />
            <geom type="mesh" class="visual" pos="-2.97454e-15 0.192752 -0.0677579" quat="0.5 -0.5 -0.5 -0.5" mesh="low_leg_right" material="low_leg_right_material" />
            <geom type="mesh" class="visual" pos="-2.9924e-16 0.192752 -0.0677579" quat="0.5 -0.5 -0.5 -0.5" mesh="low_leg_left" material="low_leg_left_material" />
            <site group="3" name="left_ankle_mimic" pos="4.95231e-05 -0.179866 0.0276306" quat="7.36303e-15 -7.37627e-15 -0.704634 -0.709571" />
            <body name="left_ankle_mimic" pos="4.95231e-05 -0.179866 0.0276306" quat="7.36303e-15 -7.37627e-15 -0.704634 -0.709571">
              <inertial pos="0 0 0" mass="0.001" diaginertia="0.000001 0.000001 0.000001" />
            </body>
            <body name="left_foot" pos="-4.74705e-05 -0.179984 0.000442075" quat="2.40923e-07 -0.00041321 0.000583051 -1">
              <joint axis="0 0 1" name="left_ankle_pitch" type="hinge" range="-0.6981317007977318 0.7853981633974483" class="htd45hServo" />
              <inertial pos="0.0185843 0.0509994 0.0268937" mass="0.311" fullinertia="0.00025348 0.000813963 0.000610718 -1.25211e-05 -1.48261e-07 -8.48921e-07" />
              <geom type="mesh" class="visual" pos="4.22839e-18 0.0435 0.1868" quat="0.5 0.5 -0.5 0.5" mesh="foot_main" material="foot_main_material" />
              <geom type="mesh" class="visual" pos="0.000150285 0.0432 0.0268" quat="0.5 0.5 -0.5 0.5" mesh="heel_btm" material="heel_btm_material" />
              <geom type="mesh" class="collision" pos="0.000150285 0.0432 0.0268" quat="0.5 0.5 -0.5 0.5" mesh="heel_btm" material="heel_btm_material" name="left_heel" />
              <geom type="mesh" class="visual" pos="-8.36518e-05 0.0432 0.0268" quat="0.5 0.5 -0.5 0.5" mesh="toe_btm" material="toe_btm_material" />
              <geom type="mesh" class="collision" pos="-8.36518e-05 0.0432 0.0268" quat="0.5 0.5 -0.5 0.5" mesh="toe_btm" material="toe_btm_material" name="left_toe" />
              <geom type="mesh" class="visual" pos="2.46114e-17 0.0732 0.0268" quat="0.5 0.5 -0.5 0.5" mesh="servo_bracket_top" material="servo_bracket_top_material" />
            </body>
          </body>
        </body>
      </body>
      <body name="right_hip" pos="4.74705e-05 -0.0536 -0.0335836" quat="0.706694 -0.707519 -0.000292013 0.000292354">
        <joint axis="0 0 1" name="right_hip_pitch" type="hinge" range="-1.5707965962257178 0.08726619316889528" class="htd45hServo" />
        <inertial pos="0.00272375 -0.00897832 -0.0331404" mass="0.0849728" fullinertia="2.00434e-05 1.92798e-05 2.44237e-05 -3.96751e-07 7.91944e-07 -1.48675e-06" />
        <geom type="mesh" class="visual" pos="-9.99909e-05 -0.03359 0.0566" quat="0.5 0.5 -0.5 0.5" mesh="hip_servo_hook_right" material="hip_servo_hook_right_material" />
        <body name="upper_leg_2" pos="0.0267 -0.000166421 -0.0364525" quat="0.706814 -0.000412355 -0.707399 -0.000412014">
          <joint axis="0 0 1" name="right_hip_roll" type="hinge" range="-0.17453292519943295 1.5707963267948966" class="htd45hServo" />
          <inertial pos="-0.00109676 0.15941 0.0267063" mass="0.236565" fullinertia="0.000988751 0.000126498 0.000981911 1.04431e-05 -1.12408e-08 1.05493e-06" />
          <geom type="mesh" class="visual" pos="-0.095 -0.0002 0.0267" quat="0.707107 0.707107 2.22045e-16 2.21178e-16" mesh="knee_ball_left" material="knee_ball_left_material" />
          <geom type="mesh" class="visual" pos="-0.095 -0.0002 0.0267" quat="0.707107 0.707107 2.22045e-16 2.21014e-16" mesh="knee_ball_mid" material="knee_ball_mid_material" />
          <geom type="mesh" class="visual" pos="-0.095 -0.0002 0.0267" quat="0.707107 0.707107 -8.32667e-15 9.96695e-15" mesh="knee_ball_right" material="knee_ball_right_material" />
          <geom type="mesh" class="visual" pos="-0.095 -8.21024e-13 0.0267" quat="0.707107 0.707107 -4.44089e-16 7.66338e-16" mesh="up_leg_servo_connect" material="up_leg_servo_connect_material" />
          <geom type="mesh" class="visual" pos="-0.095 -8.22092e-13 0.0267" quat="0.707107 0.707107 2.22045e-16 2.2109e-16" mesh="up_leg" material="up_leg_material" />
          <site group="3" name="right_knee_mimic" pos="0.000138461 0.192701 0.0266255" quat="0.49875 0.501659 0.498338 -0.501244" />
          <body name="right_knee_mimic" pos="0.000138461 0.192701 0.0266255" quat="0.49875 0.501659 0.498338 -0.501244">
            <inertial pos="0 0 0" mass="0.001" diaginertia="0.000001 0.000001 0.000001" />
          </body>
          <site group="3" name="right_knee_imu" pos="2.88658e-15 0.173352 0.0264651" quat="0.5 0.5 0.5 -0.5" />
          <body name="lower_leg_2" pos="-0.02705 0.192552 0.0267" quat="1.08512e-11 -0.707107 1.08507e-11 -0.707107">
            <joint axis="0 0 1" name="right_knee_pitch" type="hinge" range="0.0 1.3962634015954636" class="htd45hServo" />
            <inertial pos="-0.000528282 -0.102749 0.0267516" mass="0.37567" fullinertia="0.00172198 0.000666836 0.0016363 1.91588e-05 9.23751e-08 -2.38646e-05" />
            <geom type="mesh" class="visual" pos="-1.64471e-15 0.192752 -0.0677579" quat="0.5 -0.5 -0.5 -0.5" mesh="low_leg_right" material="low_leg_right_material" />
            <geom type="mesh" class="visual" pos="-2.15255e-16 0.192752 -0.0677579" quat="0.5 -0.5 -0.5 -0.5" mesh="low_leg_left" material="low_leg_left_material" />
            <site group="3" name="right_ankle_mimic" pos="4.95231e-05 -0.179866 0.0276306" quat="7.04992e-15 -7.09426e-15 -0.704634 -0.709571" />
            <body name="right_ankle_mimic" pos="4.95231e-05 -0.179866 0.0276306" quat="7.04992e-15 -7.09426e-15 -0.704634 -0.709571">
              <inertial pos="0 0 0" mass="0.001" diaginertia="0.000001 0.000001 0.000001" />
            </body>
            <body name="right_foot" pos="-4.74705e-05 -0.179984 0.000442075" quat="2.40923e-07 -0.00041321 0.000583051 -1">
              <joint axis="0 0 1" name="right_ankle_pitch" type="hinge" range="-0.6981317007977291 0.7853981633974509" class="htd45hServo" />
              <inertial pos="0.0185843 0.0509994 0.0268937" mass="0.311" fullinertia="0.00025348 0.000813963 0.000610718 -1.25211e-05 -1.48261e-07 -8.48921e-07" />
              <geom type="mesh" class="visual" pos="1.31866e-16 0.0435 0.1868" quat="0.5 0.5 -0.5 0.5" mesh="foot_main" material="foot_main_material" />
              <geom type="mesh" class="visual" pos="0.000150285 0.0432 0.0268" quat="0.5 0.5 -0.5 0.5" mesh="heel_btm" material="heel_btm_material" />
              <geom type="mesh" class="collision" pos="0.000150285 0.0432 0.0268" quat="0.5 0.5 -0.5 0.5" mesh="heel_btm" material="heel_btm_material" name="right_heel" />
              <geom type="mesh" class="visual" pos="-8.36518e-05 0.0432 0.0268" quat="0.5 0.5 -0.5 0.5" mesh="toe_btm" material="toe_btm_material" />
              <geom type="mesh" class="collision" pos="-8.36518e-05 0.0432 0.0268" quat="0.5 0.5 -0.5 0.5" mesh="toe_btm" material="toe_btm_material" name="right_toe" />
              <geom type="mesh" class="visual" pos="2.08031e-16 0.0732 0.0268" quat="0.5 0.5 -0.5 0.5" mesh="servo_bracket_top" material="servo_bracket_top_material" />
            </body>
          </body>
        </body>
      </body>
    </body>
  </worldbody>
  <asset>
    <mesh file="hip_servo_hook_left.stl" />
    <mesh file="waist_trunk_support.stl" />
    <mesh file="up_leg_servo_connect.stl" />
    <mesh file="hip_cover.stl" />
    <mesh file="knee_ball_right.stl" />
    <mesh file="foot_main.stl" />
    <mesh file="batterybox.stl" />
    <mesh file="hip_trunk_connect.stl" />
    <mesh file="cell.stl" />
    <mesh file="rp_assemble.stl" />
    <mesh file="scroll_out.stl" />
    <mesh file="heel_btm.stl" />
    <mesh file="servo_bracket_top.stl" />
    <mesh file="trunk_bottom.stl" />
    <mesh file="knee_ball_left.stl" />
    <mesh file="up_leg.stl" />
    <mesh file="low_leg_left.stl" />
    <mesh file="trunk_servo_connect.stl" />
    <mesh file="knee_ball_mid.stl" />
    <mesh file="low_leg_right.stl" />
    <mesh file="hip_servo_hook_right.stl" />
    <mesh file="toe_btm.stl" />
    <mesh file="waist_platform_2.stl" />
    <mesh file="waist_platform.stl" />
    <material name="waist_trunk_support_material" rgba="0.980392 0.713725 0.00392157 1" />
    <material name="trunk_bottom_material" rgba="0.301961 0.301961 0.301961 1" />
    <material name="trunk_servo_connect_material" rgba="0.647059 0.647059 0.647059 1" />
    <material name="hip_cover_material" rgba="0.768627 0.886275 0.952941 1" />
    <material name="scroll_out_material" rgba="0.901961 0.878431 0.811765 1" />
    <material name="hip_trunk_connect_material" rgba="0.647059 0.647059 0.647059 1" />
    <material name="cell_material" rgba="0.980392 0.713725 0.00392157 1" />
    <material name="rp_assemble_material" rgba="0.513725 0.737255 0.407843 1" />
    <material name="batterybox_material" rgba="0.301961 0.301961 0.301961 1" />
    <material name="waist_platform_material" rgba="0.231373 0.380392 0.705882 1" />
    <material name="waist_platform_2_material" rgba="0.231373 0.380392 0.705882 1" />
    <material name="hip_servo_hook_left_material" rgba="0.972549 0.529412 0.00392157 1" />
    <material name="up_leg_servo_connect_material" rgba="0.615686 0.811765 0.929412 1" />
    <material name="up_leg_material" rgba="0.647059 0.647059 0.647059 1" />
    <material name="knee_ball_left_material" rgba="0.231373 0.380392 0.705882 1" />
    <material name="knee_ball_mid_material" rgba="0.231373 0.380392 0.705882 1" />
    <material name="knee_ball_right_material" rgba="0.231373 0.380392 0.705882 1" />
    <material name="low_leg_right_material" rgba="0.498039 0.498039 0.498039 1" />
    <material name="low_leg_left_material" rgba="0.498039 0.498039 0.498039 1" />
    <material name="foot_main_material" rgba="0.980392 0.713725 0.00392157 1" />
    <material name="heel_btm_material" rgba="0.768627 0.886275 0.952941 1" />
    <material name="toe_btm_material" rgba="0.231373 0.380392 0.705882 1" />
    <material name="servo_bracket_top_material" rgba="0.4 0.4 0.4 1" />
    <material name="hip_servo_hook_right_material" rgba="0.972549 0.529412 0.00392157 1" />
  </asset>
  <actuator>
    <position class="htd45hServo" name="left_hip_pitch" joint="left_hip_pitch" inheritrange="1" />
    <position class="htd45hServo" name="left_hip_roll" joint="left_hip_roll" inheritrange="1" />
    <position class="htd45hServo" name="left_knee_pitch" joint="left_knee_pitch" inheritrange="1" />
    <position class="htd45hServo" name="left_ankle_pitch" joint="left_ankle_pitch" inheritrange="1" />
    <position class="htd45hServo" name="right_hip_pitch" joint="right_hip_pitch" inheritrange="1" />
    <position class="htd45hServo" name="right_hip_roll" joint="right_hip_roll" inheritrange="1" />
    <position class="htd45hServo" name="right_knee_pitch" joint="right_knee_pitch" inheritrange="1" />
    <position class="htd45hServo" name="right_ankle_pitch" joint="right_ankle_pitch" inheritrange="1" />
  </actuator>
  <equality />
</mujoco>