<mujoco model="WildRobot">
  <option>
    <flag eulerdamp="disable" />
  </option>
  <compiler angle="radian" meshdir="assets" autolimits="true" />
  <default>
    <default class="WildRobot">
      <joint frictionloss="0.1" armature="0.005" />
      <position kp="50" dampratio="1" />
      <default class="visual">
        <geom type="mesh" contype="0" conaffinity="0" group="2" />
      </default>
      <default class="collision">
        <geom group="3" type="sphere" />
      </default>
    </default>
    <default class="htd45hServo">
      <geom contype="0" conaffinity="0" />
      <joint damping="0.08516" frictionloss="0.022275" armature="0.024992" />
      <position kp="21.1" kv="0.5" forcerange="-4.0 4.0" />
    </default>
    <default class="backlash">
      <joint damping="0.01" frictionloss="0" armature="0.01" limited="true" range="-0.008726646259971648 0.008726646259971648" />
    </default>
  </default>
  <sensor>
    <gyro site="chest_imu" name="chest_imu_gyro" noise="0.0002" cutoff="100" />
    <accelerometer site="chest_imu" name="chest_imu_accel" noise="0.0015" cutoff="100" />
    <magnetometer site="chest_imu" name="chest_imu_mag" noise="0.3" />
    <framequat objtype="site" objname="chest_imu" name="chest_imu_quat" />
    <velocimeter site="pelvis_mimic" name="pelvis_local_linvel" />
  </sensor>
  <worldbody>
    <body name="waist" pos="0 0 0.5" quat="1 0 0 0" childclass="WildRobot">
      <freejoint name="waist_freejoint" />
      <inertial pos="-0.00188474 -3.09539e-05 0.0059955" mass="0.438621" fullinertia="0.000998015 0.000697543 0.000702081 -7.1344e-08 1.34532e-05 5.23744e-07" />
      <geom type="mesh" class="visual" pos="0.000128558 -0.000153209 0.12518" quat="0.34202 -1.65887e-17 -5.55112e-17 -0.939693" mesh="waist_trunk_support" material="waist_trunk_support_material" />
      <geom type="mesh" class="visual" pos="-1.8982e-19 0 0" quat="0.707107 0 0 -0.707107" mesh="trunk_bottom" material="trunk_bottom_material" />
      <geom type="mesh" class="visual" pos="5.89806e-17 -3.1225e-17 0" quat="0.707107 0 0 -0.707107" mesh="trunk_servo_connect" material="trunk_servo_connect_material" />
      <geom type="mesh" class="visual" pos="1.38778e-17 -0.00025 1.47949e-17" quat="0.707107 0 0 0.707107" mesh="hip_cover" material="hip_cover_material" />
      <geom type="mesh" class="visual" pos="-1.59595e-16 -1.66533e-16 0.12518" quat="0.34202 -5.80156e-17 0 -0.939693" mesh="scroll_out" material="scroll_out_material" />
      <geom type="mesh" class="visual" pos="0.000128558 0.000153209 0.12518" quat="0.939693 -2.94205e-17 -1.35637e-16 -0.34202" mesh="waist_trunk_support" material="waist_trunk_support_material" />
      <geom type="mesh" class="visual" pos="1.38778e-17 -0.0001 1.53661e-17" quat="0.707107 0 1.11022e-16 0.707107" mesh="hip_trunk_connect" material="hip_trunk_connect_material" />
      <geom type="mesh" class="visual" pos="-0.000128558 -0.000153209 0.12518" quat="0.34202 -0 -5.91646e-31 0.939693" mesh="waist_trunk_support" material="waist_trunk_support_material" />
      <geom type="mesh" class="visual" pos="-0.000128558 0.000153209 0.12518" quat="0.939693 0 -0 0.34202" mesh="waist_trunk_support" material="waist_trunk_support_material" />
      <geom type="mesh" class="visual" pos="-1.38778e-17 0.00025 1.46954e-17" quat="0.707107 0 2.22045e-16 -0.707107" mesh="hip_cover" material="hip_cover_material" />
      <geom type="mesh" class="visual" pos="-1.38778e-17 0.0001 1.3452e-17" quat="0.707107 0 1.11022e-16 -0.707107" mesh="hip_trunk_connect" material="hip_trunk_connect_material" />
      <site group="3" name="pelvis_mimic" pos="0 0 0" quat="1 0 0 0" />
      <body name="pelvis_mimic" pos="0 0 0" quat="1 0 0 0">
        <inertial pos="0 0 0" mass="0.001" diaginertia="0.000001 0.000001 0.000001" />
      </body>
      <body name="left_hip" pos="-4.74705e-05 0.0536 -0.0335836" quat="0.000292354 -0.000292013 0.707519 -0.706694">
        <joint axis="0 0 1" name="left_hip_pitch" type="hinge" range="-0.08726835630835118 1.5707944330862618" class="htd45hServo" />
        <inertial pos="-0.00291442 -0.00897832 -0.0331054" mass="0.0849728" fullinertia="2.00234e-05 1.92641e-05 2.44282e-05 3.89653e-07 -8.25998e-07 -1.4809e-06" />
        <geom type="mesh" class="visual" pos="-9.99364e-05 -0.03359 0.0566" quat="0.5 0.5 0.5 -0.5" mesh="hip_servo_hook_left" material="hip_servo_hook_left_material" />
        <body name="upper_leg" pos="-0.0269 -0.00016648 -0.0365475" quat="0.707399 -0.000412779 0.706814 0.00041312">
          <joint axis="0 0 1" name="left_hip_roll" type="hinge" range="-1.5707963267948664 0.17453292519946315" class="htd45hServo" />
          <inertial pos="-0.001125 0.15766 0.0267064" mass="0.230628" fullinertia="0.00095984 0.000124721 0.000952693 1.08972e-05 -1.17027e-08 1.05232e-06" />
          <geom type="mesh" class="visual" pos="-0.095 -4.85723e-17 0.0267" quat="0.707107 0.707107 5.44009e-15 -5.43327e-15" mesh="up_leg_servo_connect" material="up_leg_servo_connect_material" />
          <geom type="mesh" class="visual" pos="-0.095 1.4988e-15 0.0267" quat="0.707107 0.707107 1.35447e-14 -1.34176e-14" mesh="up_leg" material="up_leg_material" />
          <geom type="mesh" class="visual" pos="-0.095 -0.0002 0.0267" quat="0.707107 0.707107 1.36557e-14 -1.33446e-14" mesh="knee_ball_left" material="knee_ball_left_material" />
          <geom type="mesh" class="visual" pos="-0.095 -0.0002 0.0267" quat="0.707107 0.707107 1.36557e-14 -1.34176e-14" mesh="knee_ball_mid" material="knee_ball_mid_material" />
          <geom type="mesh" class="visual" pos="-0.095 -0.0002 0.0267" quat="0.707107 0.707107 1.36557e-14 -1.33446e-14" mesh="knee_ball_right" material="knee_ball_right_material" />
          <site group="3" name="left_knee_mimic" pos="0.000138461 0.192701 0.0266255" quat="0.49875 0.501659 0.498338 -0.501244" />
          <body name="left_knee_mimic" pos="0.000138461 0.192701 0.0266255" quat="0.49875 0.501659 0.498338 -0.501244">
            <inertial pos="0 0 0" mass="0.001" diaginertia="0.000001 0.000001 0.000001" />
          </body>
          <site group="3" name="left_knee_imu" pos="-1.06859e-15 0.173352 0.0264651" quat="0.5 0.5 0.5 -0.5" />
          <body name="lower_leg" pos="-0.02705 0.192552 0.0267" quat="1.63398e-14 -0.707107 1.62093e-14 -0.707107">
            <joint axis="0 0 1" name="left_knee_pitch" type="hinge" range="0.0 1.3962634015954636" class="htd45hServo" />
            <inertial pos="-0.000528557 -0.102714 0.0267452" mass="0.375475" fullinertia="0.00172108 0.00066678 0.0016354 1.9152e-05 9.36419e-08 -2.40247e-05" />
            <geom type="mesh" class="visual" pos="-2.97454e-15 0.192752 -0.0677579" quat="0.5 -0.5 -0.5 -0.5" mesh="low_leg_right" material="low_leg_right_material" />
            <geom type="mesh" class="visual" pos="-2.9924e-16 0.192752 -0.0677579" quat="0.5 -0.5 -0.5 -0.5" mesh="low_leg_left" material="low_leg_left_material" />
            <site group="3" name="left_ankle_mimic" pos="4.95231e-05 -0.179866 0.0276306" quat="7.36303e-15 -7.37627e-15 -0.704634 -0.709571" />
            <body name="left_ankle_mimic" pos="4.95231e-05 -0.179866 0.0276306" quat="7.36303e-15 -7.37627e-15 -0.704634 -0.709571">
              <inertial pos="0 0 0" mass="0.001" diaginertia="0.000001 0.000001 0.000001" />
            </body>
            <body name="left_foot" pos="-4.74705e-05 -0.179984 0.000442075" quat="2.40923e-07 -0.00041321 0.000583051 -1">
              <joint axis="0 0 1" name="left_ankle_pitch" type="hinge" range="-0.6981317007977318 0.7853981633974483" class="htd45hServo" />
              <inertial pos="0.0185459 0.0510575 0.0268914" mass="0.31903" fullinertia="0.000260327 0.000839893 0.000629947 -1.24841e-05 -1.49379e-07 -8.47227e-07" />
              <geom type="mesh" class="visual" pos="4.22839e-18 0.0435 0.1868" quat="0.5 0.5 -0.5 0.5" mesh="foot_main" material="foot_main_material" />
              <geom type="mesh" class="visual" pos="0.000150285 0.0432 0.0268" quat="0.5 0.5 -0.5 0.5" mesh="heel_btm" material="heel_btm_material" />
              <geom type="mesh" class="collision" pos="0.000150285 0.0432 0.0268" quat="0.5 0.5 -0.5 0.5" mesh="heel_btm" material="heel_btm_material" name="left_heel" />
              <geom type="mesh" class="visual" pos="-8.36518e-05 0.0432 0.0268" quat="0.5 0.5 -0.5 0.5" mesh="toe_btm" material="toe_btm_material" />
              <geom type="mesh" class="collision" pos="-8.36518e-05 0.0432 0.0268" quat="0.5 0.5 -0.5 0.5" mesh="toe_btm" material="toe_btm_material" name="left_toe" />
              <geom type="mesh" class="visual" pos="2.46114e-17 0.0732 0.0268" quat="0.5 0.5 -0.5 0.5" mesh="servo_bracket_top" material="servo_bracket_top_material" />
            </body>
          </body>
        </body>
      </body>
      <body name="right_hip" pos="4.74705e-05 -0.0536 -0.0335836" quat="0.706694 -0.707519 -0.000292013 0.000292354">
        <joint axis="0 0 1" name="right_hip_pitch" type="hinge" range="-1.5707965962257178 0.08726619316889528" class="htd45hServo" />
        <inertial pos="0.00272375 -0.00897832 -0.0331404" mass="0.0849728" fullinertia="2.00434e-05 1.92798e-05 2.44237e-05 -3.96751e-07 7.91944e-07 -1.48675e-06" />
        <geom type="mesh" class="visual" pos="-9.99909e-05 -0.03359 0.0566" quat="0.5 0.5 -0.5 0.5" mesh="hip_servo_hook_right" material="hip_servo_hook_right_material" />
        <body name="upper_leg_2" pos="0.0267 -0.000166421 -0.0364525" quat="0.706814 -0.000412355 -0.707399 -0.000412014">
          <joint axis="0 0 1" name="right_hip_roll" type="hinge" range="-0.17453292519943295 1.5707963267948966" class="htd45hServo" />
          <inertial pos="-0.001125 0.15766 0.0267064" mass="0.230628" fullinertia="0.00095984 0.000124721 0.000952693 1.08972e-05 -1.17027e-08 1.05232e-06" />
          <geom type="mesh" class="visual" pos="-0.095 -0.0002 0.0267" quat="0.707107 0.707107 2.22045e-16 2.21178e-16" mesh="knee_ball_left" material="knee_ball_left_material" />
          <geom type="mesh" class="visual" pos="-0.095 -0.0002 0.0267" quat="0.707107 0.707107 2.22045e-16 2.21014e-16" mesh="knee_ball_mid" material="knee_ball_mid_material" />
          <geom type="mesh" class="visual" pos="-0.095 -0.0002 0.0267" quat="0.707107 0.707107 -8.32667e-15 9.96695e-15" mesh="knee_ball_right" material="knee_ball_right_material" />
          <geom type="mesh" class="visual" pos="-0.095 -8.21024e-13 0.0267" quat="0.707107 0.707107 -4.44089e-16 7.66338e-16" mesh="up_leg_servo_connect" material="up_leg_servo_connect_material" />
          <geom type="mesh" class="visual" pos="-0.095 -8.22092e-13 0.0267" quat="0.707107 0.707107 2.22045e-16 2.2109e-16" mesh="up_leg" material="up_leg_material" />
          <site group="3" name="right_knee_mimic" pos="0.000138461 0.192701 0.0266255" quat="0.49875 0.501659 0.498338 -0.501244" />
          <body name="right_knee_mimic" pos="0.000138461 0.192701 0.0266255" quat="0.49875 0.501659 0.498338 -0.501244">
            <inertial pos="0 0 0" mass="0.001" diaginertia="0.000001 0.000001 0.000001" />
          </body>
          <site group="3" name="right_knee_imu" pos="2.88658e-15 0.173352 0.0264651" quat="0.5 0.5 0.5 -0.5" />
          <body name="lower_leg_2" pos="-0.02705 0.192552 0.0267" quat="1.08512e-11 -0.707107 1.08507e-11 -0.707107">
            <joint axis="0 0 1" name="right_knee_pitch" type="hinge" range="0.0 1.3962634015954636" class="htd45hServo" />
            <inertial pos="-0.000528557 -0.102714 0.0267452" mass="0.375475" fullinertia="0.00172108 0.00066678 0.0016354 1.9152e-05 9.36419e-08 -2.40247e-05" />
            <geom type="mesh" class="visual" pos="-1.64471e-15 0.192752 -0.0677579" quat="0.5 -0.5 -0.5 -0.5" mesh="low_leg_right" material="low_leg_right_material" />
            <geom type="mesh" class="visual" pos="-2.15255e-16 0.192752 -0.0677579" quat="0.5 -0.5 -0.5 -0.5" mesh="low_leg_left" material="low_leg_left_material" />
            <site group="3" name="right_ankle_mimic" pos="4.95231e-05 -0.179866 0.0276306" quat="7.04992e-15 -7.09426e-15 -0.704634 -0.709571" />
            <body name="right_ankle_mimic" pos="4.95231e-05 -0.179866 0.0276306" quat="7.04992e-15 -7.09426e-15 -0.704634 -0.709571">
              <inertial pos="0 0 0" mass="0.001" diaginertia="0.000001 0.000001 0.000001" />
            </body>
            <body name="right_foot" pos="-4.74705e-05 -0.179984 0.000442075" quat="2.40923e-07 -0.00041321 0.000583051 -1">
              <joint axis="0 0 1" name="right_ankle_pitch" type="hinge" range="-0.6981317007977291 0.7853981633974509" class="htd45hServo" />
              <inertial pos="0.0185459 0.0510575 0.0268914" mass="0.31903" fullinertia="0.000260327 0.000839893 0.000629947 -1.24841e-05 -1.49379e-07 -8.47227e-07" />
              <geom type="mesh" class="visual" pos="1.31866e-16 0.0435 0.1868" quat="0.5 0.5 -0.5 0.5" mesh="foot_main" material="foot_main_material" />
              <geom type="mesh" class="visual" pos="0.000150285 0.0432 0.0268" quat="0.5 0.5 -0.5 0.5" mesh="heel_btm" material="heel_btm_material" />
              <geom type="mesh" class="collision" pos="0.000150285 0.0432 0.0268" quat="0.5 0.5 -0.5 0.5" mesh="heel_btm" material="heel_btm_material" name="right_heel" />
              <geom type="mesh" class="visual" pos="-8.36518e-05 0.0432 0.0268" quat="0.5 0.5 -0.5 0.5" mesh="toe_btm" material="toe_btm_material" />
              <geom type="mesh" class="collision" pos="-8.36518e-05 0.0432 0.0268" quat="0.5 0.5 -0.5 0.5" mesh="toe_btm" material="toe_btm_material" name="right_toe" />
              <geom type="mesh" class="visual" pos="2.08031e-16 0.0732 0.0268" quat="0.5 0.5 -0.5 0.5" mesh="servo_bracket_top" material="servo_bracket_top_material" />
            </body>
          </body>
        </body>
      </body>
      <body name="upperbody" pos="1.97751e-05 4.17458e-05 0.0482" quat="0.000704463 0.707107 0.707106 0.000120096">
        <joint axis="0 0 1" name="waist_yaw" type="hinge" range="-0.5235987755982926 0.523598775598305" class="htd45hServo" />
        <inertial pos="-0.00149016 0.00828913 -0.0957464" mass="0.53402" fullinertia="0.00155112 0.00236591 0.00118613 1.70072e-05 -5.18143e-06 -3.01654e-05" />
        <geom type="mesh" class="visual" pos="-0.000246304 -0.0003 -0.0755796" quat="1.62735e-17 -0.707107 -0.707107 -9.69319e-18" mesh="waist_platform" material="waist_platform_material" />
        <geom type="mesh" class="visual" pos="-0.000246304 -0.0003 -0.0834" quat="8.04677e-17 -0.707107 0.707107 -7.8286e-17" mesh="shoulder_connect_deck" material="shoulder_connect_deck_material" />
        <geom type="mesh" class="visual" pos="-0.000246304 0.027 -0.0752" quat="0.707107 -2.1575e-15 0.707107 2.23779e-15" mesh="rp_assemble" material="rp_assemble_material" />
        <geom type="mesh" class="visual" pos="-4.63042e-05 -0.0003 -0.0834" quat="4.55358e-16 -0.707107 0.707107 -4.52831e-16" mesh="servo_support" material="servo_support_material" />
        <geom type="mesh" class="visual" pos="-0.000246304 -0.0003 -0.0834" quat="7.79856e-17 0.707107 0.707107 8.02247e-17" mesh="body_box" material="body_box_material" />
        <geom type="mesh" class="visual" pos="-0.000246304 -0.0003 -0.0834" quat="7.82539e-17 0.707107 0.707107 8.0033e-17" mesh="shoulder_connect_deck" material="shoulder_connect_deck_material" />
        <geom type="mesh" class="visual" pos="-0.000446304 -0.0003 -0.0834" quat="2.96368e-16 -0.707107 -0.707107 2.94589e-16" mesh="servo_support" material="servo_support_material" />
        <geom type="mesh" class="visual" pos="-0.000246304 -0.0003 -0.0755796" quat="2.68916e-17 -0.707107 -0.707107 5.41545e-19" mesh="waist_platform_2" material="waist_platform_2_material" />
        <site group="3" name="chest_imu" pos="1.49565e-05 -0.0003 -0.1322" quat="7.62223e-17 0.707107 0.707107 8.57062e-17" />
        <body name="shoulder" pos="-0.0816463 -0.000258254 -0.13948" quat="0.500498 0.499915 0.499502 0.500085">
          <joint axis="0 0 1" name="right_shoulder_pitch" type="hinge" range="-3.141592653589793 0.5235987755982988" class="htd45hServo" />
          <inertial pos="0.000585372 0.000147167 -0.0460385" mass="0.10784" fullinertia="4.43733e-05 4.30028e-05 2.71749e-05 -4.2417e-08 -1.30841e-08 5.88866e-08" />
          <geom type="mesh" class="visual" pos="-1.0842e-19 0.056 0.0824" quat="0.707107 0.707107 0 -1.11684e-19" mesh="shouder_connect_servo" material="shouder_connect_servo_material" />
          <geom type="mesh" class="visual" pos="-0.00035 0.056225 0.0813" quat="0.707107 0.707107 2.22045e-16 2.36453e-16" mesh="shoulder_front_ball" material="shoulder_front_ball_material" />
          <geom type="mesh" class="visual" pos="-0.00015 0.056225 0.0813" quat="0.707107 0.707107 2.22045e-16 9.39097e-17" mesh="shoulder_mid" material="shoulder_mid_material" />
          <geom type="mesh" class="visual" pos="5e-05 0.056225 0.0813" quat="0.707107 0.707107 -0 1.03093e-16" mesh="shoulder_back_ball" material="shoulder_back_ball_material" />
        </body>
        <body name="shoulder_2" pos="0.0811537 -0.000341746 -0.13948" quat="0.500498 -0.499915 -0.499502 0.500085">
          <joint axis="0 0 1" name="left_shoulder_pitch" type="hinge" range="-0.5235987755982979 3.141592653589794" class="htd45hServo" />
          <inertial pos="0.000585372 0.000147167 -0.0460385" mass="0.10784" fullinertia="4.43733e-05 4.30028e-05 2.71749e-05 -4.2417e-08 -1.30841e-08 5.88866e-08" />
          <geom type="mesh" class="visual" pos="-2.71051e-20 0.056 0.0824" quat="0.707107 0.707107 0 4.90833e-20" mesh="shouder_connect_servo" material="shouder_connect_servo_material" />
          <geom type="mesh" class="visual" pos="-0.00035 0.056225 0.0813" quat="0.707107 0.707107 0 7.16234e-17" mesh="shoulder_front_ball" material="shoulder_front_ball_material" />
          <geom type="mesh" class="visual" pos="-0.00015 0.056225 0.0813" quat="0.707107 0.707107 0 6.16458e-17" mesh="shoulder_mid" material="shoulder_mid_material" />
          <geom type="mesh" class="visual" pos="5e-05 0.056225 0.0813" quat="0.707107 0.707107 -2.22045e-16 -2.12391e-16" mesh="shoulder_back_ball" material="shoulder_back_ball_material" />
          <body name="upper_arm" pos="0.0244698 0.000340913 -0.0531165" quat="0.00275156 0.709976 0.00276929 -0.704215">
            <joint axis="0 0 1" name="left_shoulder_roll" type="hinge" range="-3.141592653589793 0.0" class="htd45hServo" />
            <inertial pos="-0.134818 0.0848391 0.0243406" mass="0.147771" fullinertia="0.000546133 0.00274879 0.00323839 3.05653e-06 -9.50615e-06 -1.25755e-05" />
            <geom type="mesh" class="visual" pos="0.1346 0.0556015 0.0256018" quat="0.500006 0.500001 0.499999 -0.499994" mesh="uparm" material="uparm_material" />
            <geom type="mesh" class="visual" pos="-0.134994 0.0562622 0.0263245" quat="0.50072 0.507363 0.500382 -0.491407" mesh="back_ball_connector" material="back_ball_connector_material" />
            <geom type="mesh" class="visual" pos="-0.134994 0.0562622 0.0263245" quat="0.50072 0.507363 0.500382 -0.491407" mesh="uparm" material="uparm_material" />
            <geom type="mesh" class="visual" pos="-0.1346 0.0555985 0.0255982" quat="0.499994 0.499999 -0.500001 0.500006" mesh="albow_servo_bracket" material="albow_servo_bracket_material" />
            <geom type="mesh" class="visual" pos="-0.134994 0.0562622 0.0263245" quat="0.50072 0.507363 0.500382 -0.491407" mesh="front_ball_connector" material="front_ball_connector_material" />
            <geom type="mesh" class="visual" pos="0.1346 0.056 0.0254" quat="0.5 0.5 0.5 -0.5" mesh="front_ball_connector" material="front_ball_connector_material" />
            <geom type="mesh" class="visual" pos="-0.134994 0.0562622 0.0263245" quat="0.50072 0.507363 0.500382 -0.491407" mesh="albow_servo_bracket" material="albow_servo_bracket_material" />
            <geom type="mesh" class="visual" pos="0.1346 0.056 0.0254" quat="0.5 0.5 0.5 -0.5" mesh="back_ball_connector" material="back_ball_connector_material" />
            <body name="shoulder_3" pos="-0.269025 0.000369553 -0.00213798" quat="0.00780859 -0.999936 -0.0011661 -0.00814713">
              <joint axis="0 0 1" name="right_shoulder_roll" type="hinge" range="0.0 3.141592653589793" class="htd45hServo" />
              <inertial pos="0.00727241 7.30683e-06 -0.0238268" mass="0.10784" fullinertia="2.71762e-05 4.30036e-05 4.43712e-05 -5.95243e-08 -1.52734e-07 5.26287e-08" />
              <geom type="mesh" class="visual" pos="0.135708 -0.0558475 -0.0229296" quat="0.495997 -0.499913 -0.503975 -0.500083" mesh="shouder_connect_servo" material="shouder_connect_servo_material" />
              <geom type="mesh" class="visual" pos="0.134611 -0.0560753 -0.0232868" quat="0.495997 -0.499913 -0.503975 -0.500083" mesh="shoulder_front_ball" material="shoulder_front_ball_material" />
              <geom type="mesh" class="visual" pos="0.134609 -0.0560737 -0.0230868" quat="0.495997 -0.499913 -0.503975 -0.500083" mesh="shoulder_mid" material="shoulder_mid_material" />
              <geom type="mesh" class="visual" pos="0.134608 -0.0560721 -0.0228868" quat="0.495997 -0.499913 -0.503975 -0.500083" mesh="shoulder_back_ball" material="shoulder_back_ball_material" />
            </body>
            <body name="fore_arm" pos="-0.293953 0.169898 0.025514" quat="0.00469695 -0.712822 -0.00634606 0.7013">
              <joint axis="0 0 1" name="right_elbow_pitch" type="hinge" range="0.0 2.0943951023931953" class="htd45hServo" />
              <inertial pos="0.000112778 -0.0325657 -0.024011" mass="0.0901921" fullinertia="0.000244561 1.3442e-05 0.000240676 3.33534e-07 1.99507e-08 -6.00183e-06" />
              <geom type="mesh" class="visual" pos="0.000159815 0.113816 -0.161498" quat="0.706694 -0.707519 0.000292013 0.000292354" mesh="forearm" material="forearm_material" />
            </body>
            <body name="fore_arm_2" pos="-0.0241014 0.1696 0.0255997" quat="0.707102 3.99965e-06 -0.707112 4.00325e-06">
              <joint axis="0 0 1" name="left_elbow_pitch" type="hinge" range="0.0 2.0943951023931953" class="htd45hServo" />
              <inertial pos="-0.000112778 0.0325657 -0.024011" mass="0.0901921" fullinertia="0.000244561 1.3442e-05 0.000240676 3.33534e-07 -1.99507e-08 6.00183e-06" />
              <geom type="mesh" class="visual" pos="-0.000159815 -0.113816 -0.161498" quat="0.000292354 0.000292013 0.707519 -0.706694" mesh="forearm" material="forearm_material" />
            </body>
          </body>
        </body>
      </body>
    </body>
  </worldbody>
  <asset>
    <mesh file="heel_btm.stl" />
    <mesh file="trunk_bottom.stl" />
    <mesh file="knee_ball_left.stl" />
    <mesh file="forearm.stl" />
    <mesh file="up_leg_servo_connect.stl" />
    <mesh file="scroll_out.stl" />
    <mesh file="shouder_connect_servo.stl" />
    <mesh file="knee_ball_right.stl" />
    <mesh file="shoulder_back_ball.stl" />
    <mesh file="waist_platform_2.stl" />
    <mesh file="shoulder_connect_deck.stl" />
    <mesh file="waist_trunk_support.stl" />
    <mesh file="low_leg_right.stl" />
    <mesh file="shoulder_mid.stl" />
    <mesh file="servo_bracket_top.stl" />
    <mesh file="front_ball_connector.stl" />
    <mesh file="albow_servo_bracket.stl" />
    <mesh file="rp_assemble.stl" />
    <mesh file="up_leg.stl" />
    <mesh file="shoulder_front_ball.stl" />
    <mesh file="knee_ball_mid.stl" />
    <mesh file="back_ball_connector.stl" />
    <mesh file="foot_main.stl" />
    <mesh file="toe_btm.stl" />
    <mesh file="trunk_servo_connect.stl" />
    <mesh file="hip_trunk_connect.stl" />
    <mesh file="body_box.stl" />
    <mesh file="hip_servo_hook_right.stl" />
    <mesh file="waist_platform.stl" />
    <mesh file="hip_servo_hook_left.stl" />
    <mesh file="low_leg_left.stl" />
    <mesh file="uparm.stl" />
    <mesh file="hip_cover.stl" />
    <mesh file="servo_support.stl" />
    <material name="waist_trunk_support_material" rgba="0.980392 0.713725 0.00392157 1" />
    <material name="trunk_bottom_material" rgba="0.301961 0.301961 0.301961 1" />
    <material name="trunk_servo_connect_material" rgba="0.647059 0.647059 0.647059 1" />
    <material name="hip_cover_material" rgba="0.768627 0.886275 0.952941 1" />
    <material name="scroll_out_material" rgba="0.901961 0.878431 0.811765 1" />
    <material name="hip_trunk_connect_material" rgba="0.647059 0.647059 0.647059 1" />
    <material name="hip_servo_hook_left_material" rgba="0.972549 0.529412 0.00392157 1" />
    <material name="up_leg_servo_connect_material" rgba="0.615686 0.811765 0.929412 1" />
    <material name="up_leg_material" rgba="0.647059 0.647059 0.647059 1" />
    <material name="knee_ball_left_material" rgba="0.231373 0.380392 0.705882 1" />
    <material name="knee_ball_mid_material" rgba="0.231373 0.380392 0.705882 1" />
    <material name="knee_ball_right_material" rgba="0.231373 0.380392 0.705882 1" />
    <material name="low_leg_right_material" rgba="0.498039 0.498039 0.498039 1" />
    <material name="low_leg_left_material" rgba="0.498039 0.498039 0.498039 1" />
    <material name="foot_main_material" rgba="0.980392 0.713725 0.00392157 1" />
    <material name="heel_btm_material" rgba="0.768627 0.886275 0.952941 1" />
    <material name="toe_btm_material" rgba="0.231373 0.380392 0.705882 1" />
    <material name="servo_bracket_top_material" rgba="0.4 0.4 0.4 1" />
    <material name="hip_servo_hook_right_material" rgba="0.972549 0.529412 0.00392157 1" />
    <material name="waist_platform_material" rgba="0.231373 0.380392 0.705882 1" />
    <material name="shoulder_connect_deck_material" rgba="0.615686 0.811765 0.929412 1" />
    <material name="rp_assemble_material" rgba="0.513725 0.737255 0.407843 1" />
    <material name="servo_support_material" rgba="0.498039 0.498039 0.498039 1" />
    <material name="body_box_material" rgba="0.768627 0.886275 0.952941 1" />
    <material name="waist_platform_2_material" rgba="0.231373 0.380392 0.705882 1" />
    <material name="shouder_connect_servo_material" rgba="0.917647 0.917647 0.917647 1" />
    <material name="shoulder_front_ball_material" rgba="0.647059 0.647059 0.647059 1" />
    <material name="shoulder_mid_material" rgba="0.917647 0.917647 0.917647 1" />
    <material name="shoulder_back_ball_material" rgba="0.980392 0.713725 0.00392157 1" />
    <material name="uparm_material" rgba="0.917647 0.917647 0.917647 1" />
    <material name="back_ball_connector_material" rgba="0.498039 0.498039 0.498039 1" />
    <material name="albow_servo_bracket_material" rgba="0.615686 0.811765 0.929412 1" />
    <material name="front_ball_connector_material" rgba="0.231373 0.380392 0.705882 1" />
    <material name="forearm_material" rgba="0.768627 0.886275 0.952941 1" />
  </asset>
  <actuator>
    <position class="htd45hServo" name="left_hip_pitch" joint="left_hip_pitch" inheritrange="1" />
    <position class="htd45hServo" name="left_hip_roll" joint="left_hip_roll" inheritrange="1" />
    <position class="htd45hServo" name="left_knee_pitch" joint="left_knee_pitch" inheritrange="1" />
    <position class="htd45hServo" name="left_ankle_pitch" joint="left_ankle_pitch" inheritrange="1" />
    <position class="htd45hServo" name="right_hip_pitch" joint="right_hip_pitch" inheritrange="1" />
    <position class="htd45hServo" name="right_hip_roll" joint="right_hip_roll" inheritrange="1" />
    <position class="htd45hServo" name="right_knee_pitch" joint="right_knee_pitch" inheritrange="1" />
    <position class="htd45hServo" name="right_ankle_pitch" joint="right_ankle_pitch" inheritrange="1" />
    <position class="htd45hServo" name="waist_yaw" joint="waist_yaw" inheritrange="1" />
    <position class="htd45hServo" name="left_shoulder_pitch" joint="left_shoulder_pitch" inheritrange="1" />
    <position class="htd45hServo" name="left_shoulder_roll" joint="left_shoulder_roll" inheritrange="1" />
    <position class="htd45hServo" name="left_elbow_pitch" joint="left_elbow_pitch" inheritrange="1" />
    <position class="htd45hServo" name="right_shoulder_pitch" joint="right_shoulder_pitch" inheritrange="1" />
    <position class="htd45hServo" name="right_shoulder_roll" joint="right_shoulder_roll" inheritrange="1" />
    <position class="htd45hServo" name="right_elbow_pitch" joint="right_elbow_pitch" inheritrange="1" />
  </actuator>
  <equality />
</mujoco>