<mujoco model="WildRobot">
  <option>
    <flag eulerdamp="disable" />
  </option>
  <compiler angle="radian" meshdir="assets" autolimits="true" />
  <default>
    <default class="WildRobot">
      <joint frictionloss="0.1" armature="0.005" />
      <position kp="50" dampratio="1" />
      <default class="visual">
        <geom type="mesh" contype="0" conaffinity="0" group="2" />
      </default>
      <default class="collision">
        <geom group="3" type="sphere" />
      </default>
    </default>
    <default class="htd45hServo">
      <geom contype="0" conaffinity="0" />
      <joint damping="0.08516" frictionloss="0.022275" armature="0.024992" />
      <position kp="21.1" kv="0.5" forcerange="-4.0 4.0" />
    </default>
    <default class="backlash">
      <joint damping="0.01" frictionloss="0" armature="0.01" limited="true" range="-0.008726646259971648 0.008726646259971648" />
    </default>
  </default>
  <sensor>
    <gyro site="chest_imu" name="chest_imu_gyro" noise="0.0002" cutoff="100" />
    <accelerometer site="chest_imu" name="chest_imu_accel" noise="0.0015" cutoff="100" />
    <magnetometer site="chest_imu" name="chest_imu_mag" noise="0.3" />
    <framequat objtype="site" objname="chest_imu" name="chest_imu_quat" />
    <velocimeter site="pelvis_mimic" name="pelvis_local_linvel" />
  </sensor>
  <worldbody>
    <body name="waist" pos="0 0 0.5" quat="1 0 0 0" childclass="WildRobot">
      <freejoint name="waist_freejoint" />
      <inertial pos="-0.00188474 -3.09539e-05 0.0059955" mass="0.438621" fullinertia="0.000998015 0.000697543 0.000702081 -7.1344e-08 1.34532e-05 5.23744e-07" />
      <geom type="mesh" class="visual" pos="0.000128558 -0.000153209 0.12518" quat="0.34202 -1.65887e-17 -5.55112e-17 -0.939693" mesh="waist_trunk_support" material="waist_trunk_support_material" />
      <geom type="mesh" class="visual" pos="-1.8982e-19 0 0" quat="0.707107 0 0 -0.707107" mesh="trunk_bottom" material="trunk_bottom_material" />
      <geom type="mesh" class="visual" pos="5.89806e-17 -3.1225e-17 0" quat="0.707107 0 0 -0.707107" mesh="trunk_servo_connect" material="trunk_servo_connect_material" />
      <geom type="mesh" class="visual" pos="1.38778e-17 -0.00025 1.47949e-17" quat="0.707107 0 0 0.707107" mesh="hip_cover" material="hip_cover_material" />
      <geom type="mesh" class="visual" pos="-1.59595e-16 -1.66533e-16 0.12518" quat="0.34202 -5.80156e-17 0 -0.939693" mesh="scroll_out" material="scroll_out_material" />
      <geom type="mesh" class="visual" pos="0.000128558 0.000153209 0.12518" quat="0.939693 -2.94205e-17 -1.35637e-16 -0.34202" mesh="waist_trunk_support" material="waist_trunk_support_material" />
      <geom type="mesh" class="visual" pos="1.38778e-17 -0.0001 1.53661e-17" quat="0.707107 0 1.11022e-16 0.707107" mesh="hip_trunk_connect" material="hip_trunk_connect_material" />
      <geom type="mesh" class="visual" pos="-0.000128558 -0.000153209 0.12518" quat="0.34202 -0 -5.91646e-31 0.939693" mesh="waist_trunk_support" material="waist_trunk_support_material" />
      <geom type="mesh" class="visual" pos="-0.000128558 0.000153209 0.12518" quat="0.939693 0 -0 0.34202" mesh="waist_trunk_support" material="waist_trunk_support_material" />
      <geom type="mesh" class="visual" pos="-1.38778e-17 0.00025 1.46954e-17" quat="0.707107 0 2.22045e-16 -0.707107" mesh="hip_cover" material="hip_cover_material" />
      <geom type="mesh" class="visual" pos="-1.38778e-17 0.0001 1.3452e-17" quat="0.707107 0 1.11022e-16 -0.707107" mesh="hip_trunk_connect" material="hip_trunk_connect_material" />
      <site group="3" name="pelvis_mimic" pos="0 0 0" quat="1 0 0 0" />
      <body name="pelvis_mimic" pos="0 0 0" quat="1 0 0 0">
        <inertial pos="0 0 0" mass="0.001" diaginertia="0.000001 0.000001 0.000001" />
      </body>
      <body name="left_hip" pos="-4.74705e-05 0.0536 -0.0335836" quat="0.000292354 -0.000292013 0.707519 -0.706694">
        <joint axis="0 0 1" name="left_hip_pitch" type="hinge" range="-0.08726835630835118 1.5707944330862618" class="htd45hServo" />
        <inertial pos="-0.00291442 -0.00897832 -0.0331054" mass="0.0849728" fullinertia="2.00234e-05 1.92641e-05 2.44282e-05 3.89653e-07 -8.25998e-07 -1.4809e-06" />
        <geom type="mesh" class="visual" pos="-9.99364e-05 -0.03359 0.0566" quat="0.5 0.5 0.5 -0.5" mesh="hip_servo_hook_left" material="hip_servo_hook_left_material" />
        <body name="upper_leg" pos="-0.0269 -0.00016648 -0.0365475" quat="0.707399 -0.000412779 0.706814 0.00041312">
          <joint axis="0 0 1" name="left_hip_roll" type="hinge" range="-1.5707963267948664 0.17453292519946315" class="htd45hServo" />
          <inertial pos="-0.001125 0.15766 0.0267064" mass="0.230628" fullinertia="0.00095984 0.000124721 0.000952693 1.08972e-05 -1.17027e-08 1.05232e-06" />
          <geom type="mesh" class="visual" pos="-0.095 -4.85723e-17 0.0267" quat="0.707107 0.707107 5.44009e-15 -5.43327e-15" mesh="up_leg_servo_connect" material="up_leg_servo_connect_material" />
          <geom type="mesh" class="visual" pos="-0.095 1.4988e-15 0.0267" quat="0.707107 0.707107 1.35447e-14 -1.34176e-14" mesh="up_leg" material="up_leg_material" />
          <geom type="mesh" class="visual" pos="-0.095 -0.0002 0.0267" quat="0.707107 0.707107 1.36557e-14 -1.33446e-14" mesh="knee_ball_left" material="knee_ball_left_material" />
          <geom type="mesh" class="visual" pos="-0.095 -0.0002 0.0267" quat="0.707107 0.707107 1.36557e-14 -1.34176e-14" mesh="knee_ball_mid" material="knee_ball_mid_material" />
          <geom type="mesh" class="visual" pos="-0.095 -0.0002 0.0267" quat="0.707107 0.707107 1.36557e-14 -1.33446e-14" mesh="knee_ball_right" material="knee_ball_right_material" />
          <site group="3" name="left_knee_mimic" pos="0.000138461 0.192701 0.0266255" quat="0.49875 0.501659 0.498338 -0.501244" />
          <body name="left_knee_mimic" pos="0.000138461 0.192701 0.0266255" quat="0.49875 0.501659 0.498338 -0.501244">
            <inertial pos="0 0 0" mass="0.001" diaginertia="0.000001 0.000001 0.000001" />
          </body>
          <site group="3" name="left_knee_imu" pos="-1.06859e-15 0.173352 0.0264651" quat="0.5 0.5 0.5 -0.5" />
          <body name="lower_leg" pos="-0.02705 0.192552 0.0267" quat="1.63398e-14 -0.707107 1.62093e-14 -0.707107">
            <joint axis="0 0 1" name="left_knee_pitch" type="hinge" range="0.0 1.3962634015954636" class="htd45hServo" />
            <inertial pos="-0.000528557 -0.102714 0.0267452" mass="0.375475" fullinertia="0.00172108 0.00066678 0.0016354 1.9152e-05 9.36419e-08 -2.40247e-05" />
            <geom type="mesh" class="visual" pos="-2.97454e-15 0.192752 -0.0677579" quat="0.5 -0.5 -0.5 -0.5" mesh="low_leg_right" material="low_leg_right_material" />
            <geom type="mesh" class="visual" pos="-2.9924e-16 0.192752 -0.0677579" quat="0.5 -0.5 -0.5 -0.5" mesh="low_leg_left" material="low_leg_left_material" />
            <site group="3" name="left_ankle_mimic" pos="4.95231e-05 -0.179866 0.0276306" quat="7.36303e-15 -7.37627e-15 -0.704634 -0.709571" />
            <body name="left_ankle_mimic" pos="4.95231e-05 -0.179866 0.0276306" quat="7.36303e-15 -7.37627e-15 -0.704634 -0.709571">
              <inertial pos="0 0 0" mass="0.001" diaginertia="0.000001 0.000001 0.000001" />
            </body>
            <body name="left_foot" pos="-4.74705e-05 -0.179984 0.000442075" quat="2.40923e-07 -0.00041321 0.000583051 -1">
              <joint axis="0 0 1" name="left_ankle_pitch" type="hinge" range="-0.6981317007977318 0.7853981633974483" class="htd45hServo" />
              <inertial pos="0.0185459 0.0510575 0.0268914" mass="0.31903" fullinertia="0.000260327 0.000839893 0.000629947 -1.24841e-05 -1.49379e-07 -8.47227e-07" />
              <geom type="mesh" class="visual" pos="4.22839e-18 0.0435 0.1868" quat="0.5 0.5 -0.5 0.5" mesh="foot_main" material="foot_main_material" />
              <geom type="mesh" class="visual" pos="0.000150285 0.0432 0.0268" quat="0.5 0.5 -0.5 0.5" mesh="heel_btm" material="heel_btm_material" />
              <geom type="mesh" class="collision" pos="0.000150285 0.0432 0.0268" quat="0.5 0.5 -0.5 0.5" mesh="heel_btm" material="heel_btm_material" name="left_heel" />
              <geom type="mesh" class="visual" pos="-8.36518e-05 0.0432 0.0268" quat="0.5 0.5 -0.5 0.5" mesh="toe_btm" material="toe_btm_material" />
              <geom type="mesh" class="collision" pos="-8.36518e-05 0.0432 0.0268" quat="0.5 0.5 -0.5 0.5" mesh="toe_btm" material="toe_btm_material" name="left_toe" />
              <geom type="mesh" class="visual" pos="2.46114e-17 0.0732 0.0268" quat="0.5 0.5 -0.5 0.5" mesh="servo_bracket_top" material="servo_bracket_top_material" />
            </body>
          </body>
        </body>
      </body>
      <body name="right_hip" pos="4.74705e-05 -0.0536 -0.0335836" quat="0.706694 -0.707519 -0.000292013 0.000292354">
        <joint axis="0 0 1" name="right_hip_pitch" type="hinge" range="-1.5707965962257178 0.08726619316889528" class="htd45hServo" />
        <inertial pos="0.00272375 -0.00897832 -0.0331404" mass="0.0849728" fullinertia="2.00434e-05 1.92798e-05 2.44237e-05 -3.96751e-07 7.91944e-07 -1.48675e-06" />
        <geom type="mesh" class="visual" pos="-9.99909e-05 -0.03359 0.0566" quat="0.5 0.5 -0.5 0.5" mesh="hip_servo_hook_right" material="hip_servo_hook_right_material" />
        <body name="upper_leg_2" pos="0.0267 -0.000166421 -0.0364525" quat="0.706814 -0.000412355 -0.707399 -0.000412014">
          <joint axis="0 0 1" name="right_hip_roll" type="hinge" range="-0.17453292519943295 1.5707963267948966" class="htd45hServo" />
          <inertial pos="-0.001125 0.15766 0.0267064" mass="0.230628" fullinertia="0.00095984 0.000124721 0.000952693 1.08972e-05 -1.17027e-08 1.05232e-06" />
          <geom type="mesh" class="visual" pos="-0.095 -0.0002 0.0267" quat="0.707107 0.707107 2.22045e-16 2.21178e-16" mesh="knee_ball_left" material="knee_ball_left_material" />
          <geom type="mesh" class="visual" pos="-0.095 -0.0002 0.0267" quat="0.707107 0.707107 2.22045e-16 2.21014e-16" mesh="knee_ball_mid" material="knee_ball_mid_material" />
          <geom type="mesh" class="visual" pos="-0.095 -0.0002 0.0267" quat="0.707107 0.707107 -8.32667e-15 9.96695e-15" mesh="knee_ball_right" material="knee_ball_right_material" />
          <geom type="mesh" class="visual" pos="-0.095 -8.21024e-13 0.0267" quat="0.707107 0.707107 -4.44089e-16 7.66338e-16" mesh="up_leg_servo_connect" material="up_leg_servo_connect_material" />
          <geom type="mesh" class="visual" pos="-0.095 -8.22092e-13 0.0267" quat="0.707107 0.707107 2.22045e-16 2.2109e-16" mesh="up_leg" material="up_leg_material" />
          <site group="3" name="right_knee_mimic" pos="0.000138461 0.192701 0.0266255" quat="0.49875 0.501659 0.498338 -0.501244" />
          <body name="right_knee_mimic" pos="0.000138461 0.192701 0.0266255" quat="0.49875 0.501659 0.498338 -0.501244">
            <inertial pos="0 0 0" mass="0.001" diaginertia="0.000001 0.000001 0.000001" />
          </body>
          <site group="3" name="right_knee_imu" pos="2.88658e-15 0.173352 0.0264651" quat="0.5 0.5 0.5 -0.5" />
          <body name="lower_leg_2" pos="-0.02705 0.192552 0.0267" quat="1.08512e-11 -0.707107 1.08507e-11 -0.707107">
            <joint axis="0 0 1" name="right_knee_pitch" type="hinge" range="0.0 1.3962634015954636" class="htd45hServo" />
            <inertial pos="-0.000528557 -0.102714 0.0267452" mass="0.375475" fullinertia="0.00172108 0.00066678 0.0016354 1.9152e-05 9.36419e-08 -2.40247e-05" />
            <geom type="mesh" class="visual" pos="-1.64471e-15 0.192752 -0.0677579" quat="0.5 -0.5 -0.5 -0.5" mesh="low_leg_right" material="low_leg_right_material" />
            <geom type="mesh" class="visual" pos="-2.15255e-16 0.192752 -0.0677579" quat="0.5 -0.5 -0.5 -0.5" mesh="low_leg_left" material="low_leg_left_material" />
            <site group="3" name="right_ankle_mimic" pos="4.95231e-05 -0.179866 0.0276306" quat="7.04992e-15 -7.09426e-15 -0.704634 -0.709571" />
            <body name="right_ankle_mimic" pos="4.95231e-05 -0.179866 0.0276306" quat="7.04992e-15 -7.09426e-15 -0.704634 -0.709571">
              <inertial pos="0 0 0" mass="0.001" diaginertia="0.000001 0.000001 0.000001" />
            </body>
            <body name="right_foot" pos="-4.74705e-05 -0.179984 0.000442075" quat="2.40923e-07 -0.00041321 0.000583051 -1">
              <joint axis="0 0 1" name="right_ankle_pitch" type="hinge" range="-0.6981317007977291 0.7853981633974509" class="htd45hServo" />
              <inertial pos="0.0185459 0.0510575 0.0268914" mass="0.31903" fullinertia="0.000260327 0.000839893 0.000629947 -1.24841e-05 -1.49379e-07 -8.47227e-07" />
              <geom type="mesh" class="visual" pos="1.31866e-16 0.0435 0.1868" quat="0.5 0.5 -0.5 0.5" mesh="foot_main" material="foot_main_material" />
              <geom type="mesh" class="visual" pos="0.000150285 0.0432 0.0268" quat="0.5 0.5 -0.5 0.5" mesh="heel_btm" material="heel_btm_material" />
              <geom type="mesh" class="collision" pos="0.000150285 0.0432 0.0268" quat="0.5 0.5 -0.5 0.5" mesh="heel_btm" material="heel_btm_material" name="right_heel" />
              <geom type="mesh" class="visual" pos="-8.36518e-05 0.0432 0.0268" quat="0.5 0.5 -0.5 0.5" mesh="toe_btm" material="toe_btm_material" />
              <geom type="mesh" class="collision" pos="-8.36518e-05 0.0432 0.0268" quat="0.5 0.5 -0.5 0.5" mesh="toe_btm" material="toe_btm_material" name="right_toe" />
              <geom type="mesh" class="visual" pos="2.08031e-16 0.0732 0.0268" quat="0.5 0.5 -0.5 0.5" mesh="servo_bracket_top" material="servo_bracket_top_material" />
            </body>
          </body>
        </body>
      </body>
      <body name="upperbody" pos="1.97751e-05 4.17458e-05 0.0482" quat="0.000704463 0.707107 0.707106 0.000120096">
        <joint axis="0 0 1" name="waist_yaw" type="hinge" range="-0.6231413140500904 0.4240562371465072" class="htd45hServo" />
        <inertial pos="-0.00230698 0.00809865 -0.0957516" mass="0.534101" fullinertia="0.00155591 0.00236132 0.00118615 -6.39013e-05 -2.16603e-06 -3.05559e-05" />
        <geom type="mesh" class="visual" pos="-0.000215272 -0.000322992 -0.0755796" quat="2.77355e-17 -0.671052 -0.74141 -3.0375e-17" mesh="waist_platform" material="waist_platform_material" />
        <geom type="mesh" class="visual" pos="-0.000215272 -0.000322992 -0.0834" quat="7.04372e-17 -0.74141 0.671052 -3.61392e-17" mesh="shoulder_connect_deck" material="shoulder_connect_deck_material" />
        <geom type="mesh" class="visual" pos="-0.0029283 0.0268419 -0.0752" quat="0.706231 -0.0351791 0.706231 0.0351791" mesh="rp_assemble" material="rp_assemble_material" />
        <geom type="mesh" class="visual" pos="-1.62616e-05 -0.000303117 -0.0834" quat="4.63298e-16 -0.74141 0.671052 -3.9171e-16" mesh="servo_support" material="servo_support_material" />
        <geom type="mesh" class="visual" pos="-0.000215272 -0.000322992 -0.0834" quat="4.58584e-17 0.671052 0.74141 8.55907e-17" mesh="body_box" material="body_box_material" />
        <geom type="mesh" class="visual" pos="-0.000215272 -0.000322992 -0.0834" quat="4.58584e-17 0.671052 0.74141 8.55907e-17" mesh="shoulder_connect_deck" material="shoulder_connect_deck_material" />
        <geom type="mesh" class="visual" pos="-0.000414281 -0.000342868 -0.0834" quat="3.10196e-16 -0.671052 -0.74141 3.07624e-16" mesh="servo_support" material="servo_support_material" />
        <geom type="mesh" class="visual" pos="-0.000215272 -0.000322992 -0.0755796" quat="2.88665e-17 -0.671052 -0.74141 -2.93248e-17" mesh="waist_platform_2" material="waist_platform_2_material" />
        <site group="3" name="chest_imu" pos="4.46959e-05 -0.000297029 -0.1322" quat="4.74741e-17 0.671052 0.74141 1.09664e-16" />
        <body name="shoulder" pos="-0.0812165 -0.00837084 -0.13948" quat="0.474999 0.474445 0.523754 0.524366">
          <joint axis="0 0 1" name="right_shoulder_pitch" type="hinge" range="-3.141592653589793 0.5235987755982988" class="htd45hServo" />
          <inertial pos="0.000402394 0.000172526 -0.0461405" mass="0.10784" fullinertia="4.43438e-05 4.29278e-05 2.71283e-05 -5.28328e-09 2.36433e-08 4.89617e-08" />
          <geom type="mesh" class="visual" pos="-4.87891e-19 0.056 0.0824" quat="0.707107 0.707107 -0 -2.73888e-18" mesh="shouder_connect_servo" material="shouder_connect_servo_material" />
          <geom type="mesh" class="visual" pos="-0.00035 0.056225 0.0813" quat="0.707107 0.707107 1.11022e-16 6.07251e-17" mesh="front_ball_connector2" material="front_ball_connector2_material" />
          <geom type="mesh" class="visual" pos="-0.00015 0.056225 0.0813" quat="0.707107 0.707107 1.11022e-16 6.67608e-17" mesh="shoulder_mid" material="shoulder_mid_material" />
          <geom type="mesh" class="visual" pos="5e-05 0.056225 0.0813" quat="0.707107 0.707107 0 1.75006e-17" mesh="front_ball_connector" material="front_ball_connector_material" />
          <body name="upper_arm" pos="0.0240371 0.000221994 -0.0536069" quat="0.501246 -0.498337 -0.498751 0.501658">
            <joint axis="0 0 1" name="right_shoulder_roll" type="hinge" range="-0.5235987755982988 3.0543261909900767" class="htd45hServo" />
            <inertial pos="0.0748366 0.00650299 0.0246353" mass="0.0589168" fullinertia="2.26373e-05 0.000152212 0.000153315 -1.12256e-05 -2.73542e-06 -2.37802e-07" />
            <geom type="mesh" class="visual" pos="0.0675181 -0.129207 0.0254" quat="0.0308436 0.706434 0.0308436 -0.706434" mesh="shoulder_ball_connector" material="shoulder_ball_connector_material" />
            <geom type="mesh" class="visual" pos="0.0679151 -0.129173 0.0252982" quat="0.030835 0.706434 0.0308443 -0.706434" mesh="uparm" material="uparm_material" />
            <geom type="mesh" class="visual" pos="0.0444557 0.139003 0.0253018" quat="0.706434 0.0308443 -0.706434 0.030835" mesh="albow_servo_bracket" material="albow_servo_bracket_material" />
            <body name="fore_arm" pos="0.147728 0.0371153 0.0253003" quat="0.521335 -0.477714 -0.521328 -0.47772">
              <joint axis="0 0 1" name="right_elbow_pitch" type="hinge" range="0.0 1.5707963267948966" class="htd45hServo" />
              <inertial pos="0.00317971 0.0664224 -0.0258005" mass="0.249555" fullinertia="0.00057701 0.000152143 0.000594926 -2.63615e-05 8.65069e-07 1.48239e-05" />
              <geom type="mesh" class="visual" pos="-0.000136633 -0.0945423 0.10789" quat="0.706694 0.707519 -0.000292013 0.000292354" mesh="forarm" material="forarm_material" />
              <geom type="mesh" class="visual" pos="8.61698e-05 -0.0942279 -0.16171" quat="0.000292354 0.000292013 0.707519 -0.706694" mesh="forarm" material="forarm_material" />
              <geom type="mesh" class="visual" pos="8.61698e-05 -0.0942279 -0.16171" quat="0.000292354 0.000292013 0.707519 -0.706694" mesh="wrist_rotation2" material="wrist_rotation2_material" />
              <geom type="mesh" class="visual" pos="8.60045e-05 -0.0942282 -0.16151" quat="0.000292354 0.000292013 0.707519 -0.706694" mesh="forearm_side_conn" material="forearm_side_conn_material" />
              <geom type="mesh" class="visual" pos="8.61698e-05 -0.0942279 -0.16171" quat="0.000292354 0.000292013 0.707519 -0.706694" mesh="wrist_servo_conn" material="wrist_servo_conn_material" />
              <geom type="mesh" class="visual" pos="8.60045e-05 -0.0942282 -0.16151" quat="0.000292354 0.000292013 0.707519 -0.706694" mesh="forearm_side_conn2" material="forearm_side_conn2_material" />
              <geom type="mesh" class="visual" pos="8.60045e-05 -0.0942282 -0.16151" quat="0.000292354 0.000292013 0.707519 -0.706694" mesh="forearm_servo_conn" material="forearm_servo_conn_material" />
              <geom type="mesh" class="visual" pos="8.61698e-05 -0.0942279 -0.16171" quat="0.000292354 0.000292013 0.707519 -0.706694" mesh="wrist_rotation1" material="wrist_rotation1_material" />
              <body name="palm" pos="-0.000195087 0.124715 -0.026813" quat="0.000119875 -0.000704102 -0.707811 0.706402">
                <joint axis="0 0 1" name="right_wrist_yaw" type="hinge" range="-1.5707963267948912 1.5707963267949019" class="htd45hServo" />
                <inertial pos="-0.00602769 -0.00287607 -0.0437887" mass="0.105296" fullinertia="0.000109052 0.000123136 3.80914e-05 2.26611e-06 -2.40527e-05 2.44206e-06" />
                <geom type="mesh" class="visual" pos="-8e-05 0.134057 0.21985" quat="1 -0 -0 2.15106e-16" mesh="palm_claw_conn" material="palm_claw_conn_material" />
                <geom type="mesh" class="visual" pos="-3.11166e-17 0.1346 0.220451" quat="1 -0 -2.22045e-16 1.38778e-17" mesh="wrist_conn" material="wrist_conn_material" />
                <geom type="mesh" class="visual" pos="-8e-05 0.134157 0.21985" quat="1 0 -4.44089e-16 1.249e-16" mesh="wrist_palm_sevo_conn" material="wrist_palm_sevo_conn_material" />
                <geom type="mesh" class="visual" pos="-8e-05 -0.135143 0.21985" quat="8.48713e-16 3.88578e-16 0 -1" mesh="finger" material="finger_material" />
                <geom type="mesh" class="visual" pos="-8e-05 0.134057 0.21985" quat="1 -0 5.55112e-16 1.80411e-16" mesh="palm_servo_bracket" material="palm_servo_bracket_material" />
                <body name="finger" pos="0.0101536 -0.0273432 -0.0336025" quat="0.499502 -0.500498 -0.499915 -0.500085">
                  <joint axis="0 0 1" name="right_wrist_pitch" type="hinge" range="0.0 0.08726646259971647" class="htd45hServo" />
                  <inertial pos="-0.0453684 0.0176533 0.024244" mass="0.0292438" fullinertia="1.0304e-05 4.10733e-05 4.11698e-05 2.37571e-06 -1.91088e-07 7.43543e-08" />
                  <geom type="mesh" class="visual" pos="0.251664 -0.0320559 0.1587" quat="0.521334 0.521334 0.477714 0.477714" mesh="finger_servo_bracket" material="finger_servo_bracket_material" />
                  <geom type="mesh" class="visual" pos="0.251664 -0.0320559 0.1587" quat="0.521334 0.521334 0.477714 0.477714" mesh="finger" material="finger_material" />
                </body>
              </body>
            </body>
          </body>
        </body>
        <body name="shoulder_2" pos="0.0807859 0.00772486 -0.13948" quat="0.474999 -0.474445 -0.523754 0.524366">
          <joint axis="0 0 1" name="left_shoulder_pitch" type="hinge" range="-0.5235987755982988 3.141592653589793" class="htd45hServo" />
          <inertial pos="0.000402394 0.000172526 -0.0461405" mass="0.10784" fullinertia="4.43438e-05 4.29278e-05 2.71283e-05 -5.28328e-09 2.36433e-08 4.89617e-08" />
          <geom type="mesh" class="visual" pos="1.97867e-18 0.056 0.0824" quat="0.707107 0.707107 -0 -2.54051e-19" mesh="shouder_connect_servo" material="shouder_connect_servo_material" />
          <geom type="mesh" class="visual" pos="-0.00035 0.056225 0.0813" quat="0.707107 0.707107 2.22045e-16 4.38091e-16" mesh="front_ball_connector2" material="front_ball_connector2_material" />
          <geom type="mesh" class="visual" pos="-0.00015 0.056225 0.0813" quat="0.707107 0.707107 3.33067e-16 2.73691e-16" mesh="shoulder_mid" material="shoulder_mid_material" />
          <geom type="mesh" class="visual" pos="5e-05 0.056225 0.0813" quat="0.707107 0.707107 -2.10942e-15 -2.32285e-15" mesh="front_ball_connector" material="front_ball_connector_material" />
          <body name="upper_arm_2" pos="0.0240371 0.000221994 -0.0536069" quat="0.501246 -0.498337 -0.498751 0.501658">
            <joint axis="0 0 1" name="left_shoulder_roll" type="hinge" range="-3.054325441095407 0.5235995254929686" class="htd45hServo" />
            <inertial pos="-0.0748289 0.00659111 0.0246353" mass="0.0589168" fullinertia="2.27051e-05 0.000152145 0.000153315 1.16102e-05 2.73516e-06 -2.40813e-07" />
            <geom type="mesh" class="visual" pos="-0.0440556 0.138969 0.0254" quat="0.706434 0.0308438 0.706434 -0.0308438" mesh="shoulder_ball_connector" material="shoulder_ball_connector_material" />
            <geom type="mesh" class="visual" pos="-0.0444526 0.139003 0.0252982" quat="0.706433 0.0308431 0.706434 -0.0308524" mesh="uparm" material="uparm_material" />
            <geom type="mesh" class="visual" pos="-0.0679181 -0.129172 0.0253018" quat="0.0308524 0.706434 -0.0308431 0.706433" mesh="albow_servo_bracket" material="albow_servo_bracket_material" />
            <body name="fore_arm_2" pos="-0.151928 -0.0108987 0.0253003" quat="0.52134 0.477708 -0.521333 0.477714">
              <joint axis="0 0 1" name="left_elbow_pitch" type="hinge" range="0.0 1.5707963267948966" class="htd45hServo" />
              <inertial pos="0.00317971 0.0664224 -0.0258005" mass="0.249555" fullinertia="0.00057701 0.000152143 0.000594926 -2.63615e-05 8.65069e-07 1.48239e-05" />
              <geom type="mesh" class="visual" pos="-0.000136633 -0.0945423 0.10789" quat="0.706694 0.707519 -0.000292013 0.000292354" mesh="forarm" material="forarm_material" />
              <geom type="mesh" class="visual" pos="8.61698e-05 -0.0942279 -0.16171" quat="0.000292354 0.000292013 0.707519 -0.706694" mesh="forarm" material="forarm_material" />
              <geom type="mesh" class="visual" pos="8.61698e-05 -0.0942279 -0.16171" quat="0.000292354 0.000292013 0.707519 -0.706694" mesh="wrist_rotation2" material="wrist_rotation2_material" />
              <geom type="mesh" class="visual" pos="8.60045e-05 -0.0942282 -0.16151" quat="0.000292354 0.000292013 0.707519 -0.706694" mesh="forearm_side_conn" material="forearm_side_conn_material" />
              <geom type="mesh" class="visual" pos="8.61698e-05 -0.0942279 -0.16171" quat="0.000292354 0.000292013 0.707519 -0.706694" mesh="wrist_servo_conn" material="wrist_servo_conn_material" />
              <geom type="mesh" class="visual" pos="8.60045e-05 -0.0942282 -0.16151" quat="0.000292354 0.000292013 0.707519 -0.706694" mesh="forearm_side_conn2" material="forearm_side_conn2_material" />
              <geom type="mesh" class="visual" pos="8.60045e-05 -0.0942282 -0.16151" quat="0.000292354 0.000292013 0.707519 -0.706694" mesh="forearm_servo_conn" material="forearm_servo_conn_material" />
              <geom type="mesh" class="visual" pos="8.61698e-05 -0.0942279 -0.16171" quat="0.000292354 0.000292013 0.707519 -0.706694" mesh="wrist_rotation1" material="wrist_rotation1_material" />
              <body name="palm_2" pos="-0.000195087 0.124715 -0.026813" quat="0.000123757 -0.000700213 -0.707811 0.706402">
                <joint axis="0 0 1" name="left_wrist_yaw" type="hinge" range="-1.5707853372991645 1.5708073162906286" class="htd45hServo" />
                <inertial pos="-0.00602769 -0.00287607 -0.0437887" mass="0.105296" fullinertia="0.000109052 0.000123136 3.80914e-05 2.26611e-06 -2.40527e-05 2.44206e-06" />
                <geom type="mesh" class="visual" pos="-8e-05 0.134057 0.21985" quat="1 -3.98738e-17 -1.38778e-16 4.85723e-16" mesh="palm_claw_conn" material="palm_claw_conn_material" />
                <geom type="mesh" class="visual" pos="-3.69035e-17 0.1346 0.220451" quat="1 -0 -6.89553e-17 -9.62314e-17" mesh="wrist_conn" material="wrist_conn_material" />
                <geom type="mesh" class="visual" pos="-8e-05 0.134157 0.21985" quat="1 6.55603e-18 -5.55112e-17 5.27356e-16" mesh="wrist_palm_sevo_conn" material="wrist_palm_sevo_conn_material" />
                <geom type="mesh" class="visual" pos="-8e-05 -0.135143 0.21985" quat="1.11022e-15 1.03406e-16 6.10623e-16 -1" mesh="finger" material="finger_material" />
                <geom type="mesh" class="visual" pos="-8e-05 0.134057 0.21985" quat="1 4.34071e-18 -7.28584e-17 3.93132e-16" mesh="palm_servo_bracket" material="palm_servo_bracket_material" />
                <body name="finger_2" pos="0.0101536 -0.0273432 -0.0336025" quat="0.499502 -0.500498 -0.499915 -0.500085">
                  <joint axis="0 0 1" name="left_wrist_pitch" type="hinge" range="-6.424186930074904e-05 0.08720222073041572" class="htd45hServo" />
                  <inertial pos="-0.0453695 0.0176504 0.024244" mass="0.0292438" fullinertia="1.03037e-05 4.10736e-05 4.11698e-05 2.37374e-06 -1.91093e-07 7.4342e-08" />
                  <geom type="mesh" class="visual" pos="0.251666 -0.0320398 0.1587" quat="0.521318 0.521318 0.477731 0.477731" mesh="finger_servo_bracket" material="finger_servo_bracket_material" />
                  <geom type="mesh" class="visual" pos="0.251666 -0.0320398 0.1587" quat="0.521318 0.521318 0.477731 0.477731" mesh="finger" material="finger_material" />
                </body>
              </body>
            </body>
          </body>
        </body>
      </body>
    </body>
  </worldbody>
  <asset>
    <mesh file="hip_servo_hook_right.stl" />
    <mesh file="albow_servo_bracket.stl" />
    <mesh file="wrist_servo_conn.stl" />
    <mesh file="waist_trunk_support.stl" />
    <mesh file="up_leg.stl" />
    <mesh file="knee_ball_left.stl" />
    <mesh file="hip_cover.stl" />
    <mesh file="wrist_rotation1.stl" />
    <mesh file="toe_btm.stl" />
    <mesh file="wrist_rotation2.stl" />
    <mesh file="servo_support.stl" />
    <mesh file="low_leg_right.stl" />
    <mesh file="trunk_bottom.stl" />
    <mesh file="shoulder_ball_connector.stl" />
    <mesh file="wrist_conn.stl" />
    <mesh file="knee_ball_mid.stl" />
    <mesh file="scroll_out.stl" />
    <mesh file="wrist_palm_sevo_conn.stl" />
    <mesh file="rp_assemble.stl" />
    <mesh file="foot_main.stl" />
    <mesh file="trunk_servo_connect.stl" />
    <mesh file="forarm.stl" />
    <mesh file="up_leg_servo_connect.stl" />
    <mesh file="palm_claw_conn.stl" />
    <mesh file="waist_platform_2.stl" />
    <mesh file="waist_platform.stl" />
    <mesh file="shoulder_connect_deck.stl" />
    <mesh file="finger_servo_bracket.stl" />
    <mesh file="finger.stl" />
    <mesh file="palm_servo_bracket.stl" />
    <mesh file="front_ball_connector2.stl" />
    <mesh file="hip_servo_hook_left.stl" />
    <mesh file="forearm_side_conn.stl" />
    <mesh file="servo_bracket_top.stl" />
    <mesh file="hip_trunk_connect.stl" />
    <mesh file="forearm_servo_conn.stl" />
    <mesh file="front_ball_connector.stl" />
    <mesh file="knee_ball_right.stl" />
    <mesh file="heel_btm.stl" />
    <mesh file="shoulder_mid.stl" />
    <mesh file="low_leg_left.stl" />
    <mesh file="body_box.stl" />
    <mesh file="uparm.stl" />
    <mesh file="shouder_connect_servo.stl" />
    <mesh file="forearm_side_conn2.stl" />
    <material name="waist_trunk_support_material" rgba="0.980392 0.713725 0.00392157 1" />
    <material name="trunk_bottom_material" rgba="0.301961 0.301961 0.301961 1" />
    <material name="trunk_servo_connect_material" rgba="0.647059 0.647059 0.647059 1" />
    <material name="hip_cover_material" rgba="0.768627 0.886275 0.952941 1" />
    <material name="scroll_out_material" rgba="0.901961 0.878431 0.811765 1" />
    <material name="hip_trunk_connect_material" rgba="0.647059 0.647059 0.647059 1" />
    <material name="hip_servo_hook_left_material" rgba="0.972549 0.529412 0.00392157 1" />
    <material name="up_leg_servo_connect_material" rgba="0.615686 0.811765 0.929412 1" />
    <material name="up_leg_material" rgba="0.647059 0.647059 0.647059 1" />
    <material name="knee_ball_left_material" rgba="0.231373 0.380392 0.705882 1" />
    <material name="knee_ball_mid_material" rgba="0.231373 0.380392 0.705882 1" />
    <material name="knee_ball_right_material" rgba="0.231373 0.380392 0.705882 1" />
    <material name="low_leg_right_material" rgba="0.498039 0.498039 0.498039 1" />
    <material name="low_leg_left_material" rgba="0.498039 0.498039 0.498039 1" />
    <material name="foot_main_material" rgba="0.980392 0.713725 0.00392157 1" />
    <material name="heel_btm_material" rgba="0.768627 0.886275 0.952941 1" />
    <material name="toe_btm_material" rgba="0.231373 0.380392 0.705882 1" />
    <material name="servo_bracket_top_material" rgba="0.4 0.4 0.4 1" />
    <material name="hip_servo_hook_right_material" rgba="0.972549 0.529412 0.00392157 1" />
    <material name="waist_platform_material" rgba="0.231373 0.380392 0.705882 1" />
    <material name="shoulder_connect_deck_material" rgba="0.615686 0.811765 0.929412 1" />
    <material name="rp_assemble_material" rgba="0.513725 0.737255 0.407843 1" />
    <material name="servo_support_material" rgba="0.498039 0.498039 0.498039 1" />
    <material name="body_box_material" rgba="0.768627 0.886275 0.952941 1" />
    <material name="waist_platform_2_material" rgba="0.231373 0.380392 0.705882 1" />
    <material name="shouder_connect_servo_material" rgba="0.917647 0.917647 0.917647 1" />
    <material name="front_ball_connector2_material" rgba="0.615686 0.811765 0.929412 1" />
    <material name="shoulder_mid_material" rgba="0.917647 0.917647 0.917647 1" />
    <material name="front_ball_connector_material" rgba="0.498039 0.498039 0.498039 1" />
    <material name="shoulder_ball_connector_material" rgba="0.647059 0.647059 0.647059 1" />
    <material name="uparm_material" rgba="0.917647 0.917647 0.917647 1" />
    <material name="albow_servo_bracket_material" rgba="0.615686 0.811765 0.929412 1" />
    <material name="forarm_material" rgba="0.917647 0.917647 0.917647 1" />
    <material name="wrist_rotation2_material" rgba="0.980392 0.713725 0.00392157 1" />
    <material name="forearm_side_conn_material" rgba="0.647059 0.647059 0.647059 1" />
    <material name="wrist_servo_conn_material" rgba="0.615686 0.811765 0.929412 1" />
    <material name="forearm_side_conn2_material" rgba="0.647059 0.647059 0.647059 1" />
    <material name="forearm_servo_conn_material" rgba="0.768627 0.886275 0.952941 1" />
    <material name="wrist_rotation1_material" rgba="0.980392 0.713725 0.00392157 1" />
    <material name="palm_claw_conn_material" rgba="0.498039 0.498039 0.498039 1" />
    <material name="wrist_conn_material" rgba="0.980392 0.713725 0.00392157 1" />
    <material name="wrist_palm_sevo_conn_material" rgba="0.768627 0.886275 0.952941 1" />
    <material name="finger_material" rgba="0.972549 0.529412 0.00392157 1" />
    <material name="palm_servo_bracket_material" rgba="0.972549 0.529412 0.00392157 1" />
    <material name="finger_servo_bracket_material" rgba="0.615686 0.811765 0.929412 1" />
  </asset>
  <actuator>
    <position class="htd45hServo" name="left_hip_pitch" joint="left_hip_pitch" inheritrange="1" />
    <position class="htd45hServo" name="left_hip_roll" joint="left_hip_roll" inheritrange="1" />
    <position class="htd45hServo" name="left_knee_pitch" joint="left_knee_pitch" inheritrange="1" />
    <position class="htd45hServo" name="left_ankle_pitch" joint="left_ankle_pitch" inheritrange="1" />
    <position class="htd45hServo" name="right_hip_pitch" joint="right_hip_pitch" inheritrange="1" />
    <position class="htd45hServo" name="right_hip_roll" joint="right_hip_roll" inheritrange="1" />
    <position class="htd45hServo" name="right_knee_pitch" joint="right_knee_pitch" inheritrange="1" />
    <position class="htd45hServo" name="right_ankle_pitch" joint="right_ankle_pitch" inheritrange="1" />
    <position class="htd45hServo" name="waist_yaw" joint="waist_yaw" inheritrange="1" />
    <position class="htd45hServo" name="left_shoulder_pitch" joint="left_shoulder_pitch" inheritrange="1" />
    <position class="htd45hServo" name="left_shoulder_roll" joint="left_shoulder_roll" inheritrange="1" />
    <position class="htd45hServo" name="left_elbow_pitch" joint="left_elbow_pitch" inheritrange="1" />
    <position class="htd45hServo" name="left_wrist_yaw" joint="left_wrist_yaw" inheritrange="1" />
    <position class="htd45hServo" name="left_wrist_pitch" joint="left_wrist_pitch" inheritrange="1" />
    <position class="htd45hServo" name="right_shoulder_pitch" joint="right_shoulder_pitch" inheritrange="1" />
    <position class="htd45hServo" name="right_shoulder_roll" joint="right_shoulder_roll" inheritrange="1" />
    <position class="htd45hServo" name="right_elbow_pitch" joint="right_elbow_pitch" inheritrange="1" />
    <position class="htd45hServo" name="right_wrist_yaw" joint="right_wrist_yaw" inheritrange="1" />
    <position class="htd45hServo" name="right_wrist_pitch" joint="right_wrist_pitch" inheritrange="1" />
  </actuator>
  <equality />
</mujoco>