<mujoco model="WildRobot">
  <compiler angle="radian" meshdir="assets" autolimits="true" />
  <default>
    <default class="WildRobot">
      <joint frictionloss="0.1" armature="0.005" />
      <position kp="50" dampratio="1" />
      <default class="visual">
        <geom type="mesh" contype="0" conaffinity="0" group="2" />
      </default>
      <default class="collision">
        <geom group="3" />
      </default>
    </default>
  </default>
  <sensor>
    <gyro site="chest_imu" name="chest_imu_gyro" noise="0.0002" cutoff="100" />
    <accelerometer site="chest_imu" name="chest_imu_accel" noise="0.0015" cutoff="100" />
    <magnetometer site="chest_imu" name="chest_imu_mag" noise="0.3" />
    <framequat objtype="site" objname="chest_imu" name="chest_imu_quat" />
    <velocimeter site="pelvis_mimic" name="pelvis_local_linvel" />
  </sensor>
  <default>
    <default class="htd45hServo">
      <geom contype="0" conaffinity="0" />
      <joint damping="0.08516" frictionloss="0.022275" armature="0.024992" />
      <position kp="21.1" kv="0.5" forcerange="-4.0 4.0" />
    </default>
    <default class="backlash">
      <joint damping="0.01" frictionloss="0" armature="0.01" limited="true" range="-0.008726646259971648 0.008726646259971648" />
    </default>
  </default>
  <worldbody>
    <body name="waist" pos="0 0 0" quat="1 0 0 0" childclass="WildRobot">
      <freejoint name="waist_freejoint" />
      <inertial pos="-0.00188474 -3.09539e-05 0.0059955" mass="0.438621" fullinertia="0.000998015 0.000697543 0.000702081 -7.1344e-08 1.34532e-05 5.23744e-07" />
      <geom type="mesh" class="visual" pos="-0.0596393 -0.00143119 -0.0273687" quat="0.706991 0.707223 -0 2.16453e-17" mesh="htd_45h_1circle" material="htd_45h_1circle_material" />
      <geom type="mesh" class="visual" pos="0.000128558 -0.000153209 0.12518" quat="0.34202 -1.65887e-17 -5.55112e-17 -0.939693" mesh="waist_trunk_support" material="waist_trunk_support_material" />
      <geom type="mesh" class="visual" pos="-1.8982e-19 0 0" quat="0.707107 0 0 -0.707107" mesh="trunk_bottom" material="trunk_bottom_material" />
      <geom type="mesh" class="visual" pos="-0.00619509 -0.059645 -0.00396881" quat="0.707107 0.000116219 0.000116219 0.707107" mesh="htd_45h_1circle" material="htd_45h_1circle_material" />
      <geom type="mesh" class="visual" pos="5.89806e-17 -3.1225e-17 0" quat="0.707107 0 0 -0.707107" mesh="trunk_servo_connect" material="trunk_servo_connect_material" />
      <geom type="mesh" class="visual" pos="1.38778e-17 -0.00025 1.47949e-17" quat="0.707107 0 0 0.707107" mesh="hip_cover" material="hip_cover_material" />
      <geom type="mesh" class="visual" pos="-1.59595e-16 -1.66533e-16 0.12518" quat="0.34202 -5.80156e-17 0 -0.939693" mesh="scroll_out" material="scroll_out_material" />
      <geom type="mesh" class="visual" pos="0.000128558 0.000153209 0.12518" quat="0.939693 -2.94205e-17 -1.35637e-16 -0.34202" mesh="waist_trunk_support" material="waist_trunk_support_material" />
      <geom type="mesh" class="visual" pos="1.38778e-17 -0.0001 1.53661e-17" quat="0.707107 0 1.11022e-16 0.707107" mesh="hip_trunk_connect" material="hip_trunk_connect_material" />
      <geom type="mesh" class="visual" pos="-0.000128558 -0.000153209 0.12518" quat="0.34202 -0 -5.91646e-31 0.939693" mesh="waist_trunk_support" material="waist_trunk_support_material" />
      <geom type="mesh" class="visual" pos="-0.000257115 -0.000306418 0.12518" quat="0.939693 -9.10309e-17 0 0.34202" mesh="scroll_inner" material="scroll_inner_material" />
      <geom type="mesh" class="visual" pos="-0.000128558 0.000153209 0.12518" quat="0.939693 0 -0 0.34202" mesh="waist_trunk_support" material="waist_trunk_support_material" />
      <geom type="mesh" class="visual" pos="-1.38778e-17 0.00025 1.46954e-17" quat="0.707107 0 2.22045e-16 -0.707107" mesh="hip_cover" material="hip_cover_material" />
      <geom type="mesh" class="visual" pos="0.0596393 0.00143119 -0.0273687" quat="2.16453e-17 0 -0.707223 -0.706991" mesh="htd_45h_1circle" material="htd_45h_1circle_material" />
      <geom type="mesh" class="visual" pos="-1.38778e-17 0.0001 1.3452e-17" quat="0.707107 0 1.11022e-16 -0.707107" mesh="hip_trunk_connect" material="hip_trunk_connect_material" />
      <site group="3" name="pelvis_mimic" pos="0 0 0" quat="1 0 0 0" />
      <body name="left_hip" pos="-4.74705e-05 0.0536 -0.0335836" quat="0.000292354 -0.000292013 0.707519 -0.706694">
        <joint axis="0 0 1" name="left_hip_pitch" type="hinge" range="-0.08726835630835118 1.5707944330862618" class="htd45hServo" />
        <inertial pos="-0.00291442 -0.00897832 -0.0331054" mass="0.0849728" fullinertia="2.00234e-05 1.92641e-05 2.44282e-05 3.89653e-07 -8.25998e-07 -1.4809e-06" />
        <geom type="mesh" class="visual" pos="-9.99364e-05 -0.03359 0.0566" quat="0.5 0.5 0.5 -0.5" mesh="hip_servo_hook_left" material="hip_servo_hook_left_material" />
        <geom type="mesh" class="visual" pos="0.0252688 -0.00638125 0.0231393" quat="0.000115549 -0.707107 0.000115549 0.707107" mesh="htd_45h_1circle" material="htd_45h_1circle_material" />
        <geom type="mesh" class="visual" pos="6.40831e-08 -0.03384 0.054" quat="0.5 0.5 0.5 -0.5" mesh="hip_servo_gear" material="hip_servo_gear_material" />
        <geom type="mesh" class="visual" pos="-9.99364e-05 -0.03359 0.0529" quat="0.5 0.5 0.5 -0.5" mesh="hip_gear" material="hip_gear_material" />
        <body name="upper_leg" pos="-0.0269 -0.00016648 -0.0365475" quat="0.707399 -0.000412779 0.706814 0.00041312">
          <joint axis="0 0 1" name="left_hip_roll" type="hinge" range="-1.5707963267948664 0.17453292519946315" class="htd45hServo" />
          <inertial pos="-0.001125 0.15766 0.0267064" mass="0.230628" fullinertia="0.00095984 0.000124721 0.000952693 1.08972e-05 -1.17027e-08 1.05232e-06" />
          <geom type="mesh" class="visual" pos="-0.095 -4.85723e-17 0.0267" quat="0.707107 0.707107 5.44009e-15 -5.43327e-15" mesh="up_leg_servo_connect" material="up_leg_servo_connect_material" />
          <geom type="mesh" class="visual" pos="-0.095 1.4988e-15 0.0267" quat="0.707107 0.707107 1.35447e-14 -1.34176e-14" mesh="up_leg" material="up_leg_material" />
          <geom type="mesh" class="visual" pos="6.28664e-15 0.174352 0.1872" quat="0.5 0.5 0.5 -0.5" mesh="icm45686" material="icm45686_material" />
          <geom type="mesh" class="visual" pos="-0.095 -0.0002 0.0267" quat="0.707107 0.707107 1.36557e-14 -1.33446e-14" mesh="knee_ball_left" material="knee_ball_left_material" />
          <geom type="mesh" class="visual" pos="-0.095 -0.0002 0.0267" quat="0.707107 0.707107 1.36557e-14 -1.34176e-14" mesh="knee_ball_mid" material="knee_ball_mid_material" />
          <geom type="mesh" class="visual" pos="0.0251608 0.198828 -0.0329436" quat="0.706814 0.00052828 -0.707399 0.000528717" mesh="htd_45h_1circle" material="htd_45h_1circle_material" />
          <geom type="mesh" class="visual" pos="-0.095 -0.0002 0.0267" quat="0.707107 0.707107 1.36557e-14 -1.33446e-14" mesh="knee_ball_right" material="knee_ball_right_material" />
          <site group="3" name="left_knee_mimic" pos="0.000138461 0.192701 0.0266255" quat="0.49875 0.501659 0.498338 -0.501244" />
          <site group="3" name="left_knee_imu" pos="-1.06859e-15 0.173352 0.0264651" quat="0.5 0.5 0.5 -0.5" />
          <body name="lower_leg" pos="-0.02705 0.192552 0.0267" quat="1.63398e-14 -0.707107 1.62093e-14 -0.707107">
            <joint axis="0 0 1" name="left_knee_pitch" type="hinge" range="0.0 1.3962634015954636" class="htd45hServo" />
            <inertial pos="-0.000528557 -0.102714 0.0267452" mass="0.375475" fullinertia="0.00172108 0.00066678 0.0016354 1.9152e-05 9.36419e-08 -2.40247e-05" />
            <geom type="mesh" class="visual" pos="-6.03087e-17 0.192752 -0.0678" quat="0.5 -0.5 -0.5 -0.5" mesh="knee_ball_servo_connect_3" material="knee_ball_servo_connect_3_material" />
            <geom type="mesh" class="visual" pos="-2.97454e-15 0.192752 -0.0677579" quat="0.5 -0.5 -0.5 -0.5" mesh="low_leg_right" material="low_leg_right_material" />
            <geom type="mesh" class="visual" pos="-2.9924e-16 0.192752 -0.0677579" quat="0.5 -0.5 -0.5 -0.5" mesh="low_leg_left" material="low_leg_left_material" />
            <geom type="mesh" class="visual" pos="-2.7929e-15 0.192752 -0.0677579" quat="0.5 -0.5 -0.5 -0.5" mesh="knee_ball_servo_connect_2" material="knee_ball_servo_connect_2_material" />
            <geom type="mesh" class="visual" pos="-2.80082e-15 0.192752 -0.0677579" quat="0.5 -0.5 -0.5 -0.5" mesh="low_leg_servo_connect" material="low_leg_servo_connect_material" />
            <geom type="mesh" class="visual" pos="-2.41289e-16 0.192752 -0.0676" quat="0.5 -0.5 -0.5 -0.5" mesh="knee_ball_servo_connect_1" material="knee_ball_servo_connect_1_material" />
            <geom type="mesh" class="visual" pos="0.0596393 -0.173769 0.0526109" quat="1.05471e-14 0 -1 0.000164358" mesh="htd_45h_1circle" material="htd_45h_1circle_material" />
            <site group="3" name="left_ankle_mimic" pos="4.95231e-05 -0.179866 0.0276306" quat="7.36303e-15 -7.37627e-15 -0.704634 -0.709571" />
            <body name="left_foot" pos="-4.74705e-05 -0.179984 0.000442075" quat="2.40923e-07 -0.00041321 0.000583051 -1">
              <joint axis="0 0 1" name="left_ankle_pitch" type="hinge" range="-0.6981317007977318 0.7853981633974483" class="htd45hServo" />
              <inertial pos="0.0185459 0.0510575 0.0268914" mass="0.31903" fullinertia="0.000260327 0.000839893 0.000629947 -1.24841e-05 -1.49379e-07 -8.47227e-07" />
              <geom type="mesh" class="visual" pos="0.000150285 0.0433 0.0268" quat="0.5 0.5 -0.5 0.5" mesh="heel_top" material="heel_top_material" />
              <geom type="mesh" class="visual" pos="4.22839e-18 0.0435 0.1868" quat="0.5 0.5 -0.5 0.5" mesh="foot_main" material="foot_main_material" />
              <geom type="mesh" class="visual" pos="0.000150285 0.0432 0.0268" quat="0.5 0.5 -0.5 0.5" mesh="heel_btm" material="heel_btm_material" />
              <geom type="mesh" class="visual" pos="-8.36518e-05 0.0432 0.0268" quat="0.5 0.5 -0.5 0.5" mesh="toe_btm" material="toe_btm_material" />
              <geom type="mesh" class="visual" pos="2.46114e-17 0.0732 0.0268" quat="0.5 0.5 -0.5 0.5" mesh="servo_bracket_top" material="servo_bracket_top_material" />
              <geom type="mesh" class="visual" pos="-8.36518e-05 0.0433 0.0268" quat="0.5 0.5 -0.5 0.5" mesh="toe_top" material="toe_top_material" />
            </body>
          </body>
        </body>
      </body>
      <body name="right_hip" pos="4.74705e-05 -0.0536 -0.0335836" quat="0.706694 -0.707519 -0.000292013 0.000292354">
        <joint axis="0 0 1" name="right_hip_pitch" type="hinge" range="-1.5707965962257178 0.08726619316889528" class="htd45hServo" />
        <inertial pos="0.00272375 -0.00897832 -0.0331404" mass="0.0849728" fullinertia="2.00434e-05 1.92798e-05 2.44237e-05 -3.96751e-07 7.91944e-07 -1.48675e-06" />
        <geom type="mesh" class="visual" pos="-0.0254688 -0.0063813 -0.0961393" quat="0.000116314 -0.707107 -0.000116314 -0.707107" mesh="htd_45h_1circle" material="htd_45h_1circle_material" />
        <geom type="mesh" class="visual" pos="9.11754e-09 -0.03384 0.054" quat="0.5 0.5 0.5 -0.5" mesh="hip_servo_gear" material="hip_servo_gear_material" />
        <geom type="mesh" class="visual" pos="-9.99909e-05 -0.03359 0.0566" quat="0.5 0.5 -0.5 0.5" mesh="hip_servo_hook_right" material="hip_servo_hook_right_material" />
        <geom type="mesh" class="visual" pos="-9.99909e-05 -0.03359 0.0529" quat="0.5 0.5 0.5 -0.5" mesh="hip_gear" material="hip_gear_material" />
        <body name="upper_leg_2" pos="0.0267 -0.000166421 -0.0364525" quat="0.706814 -0.000412355 -0.707399 -0.000412014">
          <joint axis="0 0 1" name="right_hip_roll" type="hinge" range="-0.17453292519943295 1.5707963267948966" class="htd45hServo" />
          <inertial pos="-0.001125 0.15766 0.0267064" mass="0.230628" fullinertia="0.00095984 0.000124721 0.000952693 1.08972e-05 -1.17027e-08 1.05232e-06" />
          <geom type="mesh" class="visual" pos="2.58127e-15 0.174352 0.1872" quat="0.5 0.5 0.5 -0.5" mesh="icm45686" material="icm45686_material" />
          <geom type="mesh" class="visual" pos="-0.095 -0.0002 0.0267" quat="0.707107 0.707107 2.22045e-16 2.21178e-16" mesh="knee_ball_left" material="knee_ball_left_material" />
          <geom type="mesh" class="visual" pos="-0.095 -0.0002 0.0267" quat="0.707107 0.707107 2.22045e-16 2.21014e-16" mesh="knee_ball_mid" material="knee_ball_mid_material" />
          <geom type="mesh" class="visual" pos="0.0251608 0.198828 -0.0329436" quat="0.706814 0.00052828 -0.707399 0.000528717" mesh="htd_45h_1circle" material="htd_45h_1circle_material" />
          <geom type="mesh" class="visual" pos="-0.095 -0.0002 0.0267" quat="0.707107 0.707107 -8.32667e-15 9.96695e-15" mesh="knee_ball_right" material="knee_ball_right_material" />
          <geom type="mesh" class="visual" pos="-0.095 -8.21024e-13 0.0267" quat="0.707107 0.707107 -4.44089e-16 7.66338e-16" mesh="up_leg_servo_connect" material="up_leg_servo_connect_material" />
          <geom type="mesh" class="visual" pos="-0.095 -8.22092e-13 0.0267" quat="0.707107 0.707107 2.22045e-16 2.2109e-16" mesh="up_leg" material="up_leg_material" />
          <site group="3" name="right_knee_mimic" pos="0.000138461 0.192701 0.0266255" quat="0.49875 0.501659 0.498338 -0.501244" />
          <site group="3" name="right_knee_imu" pos="2.88658e-15 0.173352 0.0264651" quat="0.5 0.5 0.5 -0.5" />
          <body name="lower_leg_2" pos="-0.02705 0.192552 0.0267" quat="1.08512e-11 -0.707107 1.08507e-11 -0.707107">
            <joint axis="0 0 1" name="right_knee_pitch" type="hinge" range="0.0 1.3962634015954636" class="htd45hServo" />
            <inertial pos="-0.000528557 -0.102714 0.0267452" mass="0.375475" fullinertia="0.00172108 0.00066678 0.0016354 1.9152e-05 9.36419e-08 -2.40247e-05" />
            <geom type="mesh" class="visual" pos="-6.03223e-17 0.192752 -0.0678" quat="0.5 -0.5 -0.5 -0.5" mesh="knee_ball_servo_connect_3" material="knee_ball_servo_connect_3_material" />
            <geom type="mesh" class="visual" pos="-1.64471e-15 0.192752 -0.0677579" quat="0.5 -0.5 -0.5 -0.5" mesh="low_leg_right" material="low_leg_right_material" />
            <geom type="mesh" class="visual" pos="-2.15255e-16 0.192752 -0.0677579" quat="0.5 -0.5 -0.5 -0.5" mesh="low_leg_left" material="low_leg_left_material" />
            <geom type="mesh" class="visual" pos="-1.44507e-15 0.192752 -0.0677579" quat="0.5 -0.5 -0.5 -0.5" mesh="knee_ball_servo_connect_2" material="knee_ball_servo_connect_2_material" />
            <geom type="mesh" class="visual" pos="-1.87441e-15 0.192752 -0.0677579" quat="0.5 -0.5 -0.5 -0.5" mesh="low_leg_servo_connect" material="low_leg_servo_connect_material" />
            <geom type="mesh" class="visual" pos="-9.56944e-17 0.192752 -0.0676" quat="0.5 -0.5 -0.5 -0.5" mesh="knee_ball_servo_connect_1" material="knee_ball_servo_connect_1_material" />
            <geom type="mesh" class="visual" pos="0.0596393 -0.173769 0.0526109" quat="1.0103e-14 2.23829e-17 -1 0.000164358" mesh="htd_45h_1circle" material="htd_45h_1circle_material" />
            <site group="3" name="right_ankle_mimic" pos="4.95231e-05 -0.179866 0.0276306" quat="7.04992e-15 -7.09426e-15 -0.704634 -0.709571" />
            <body name="right_foot" pos="-4.74705e-05 -0.179984 0.000442075" quat="2.40923e-07 -0.00041321 0.000583051 -1">
              <joint axis="0 0 1" name="right_ankle_pitch" type="hinge" range="-0.6981317007977291 0.7853981633974509" class="htd45hServo" />
              <inertial pos="0.0185459 0.0510575 0.0268914" mass="0.31903" fullinertia="0.000260327 0.000839893 0.000629947 -1.24841e-05 -1.49379e-07 -8.47227e-07" />
              <geom type="mesh" class="visual" pos="0.000150285 0.0433 0.0268" quat="0.5 0.5 -0.5 0.5" mesh="heel_top" material="heel_top_material" />
              <geom type="mesh" class="visual" pos="1.31866e-16 0.0435 0.1868" quat="0.5 0.5 -0.5 0.5" mesh="foot_main" material="foot_main_material" />
              <geom type="mesh" class="visual" pos="0.000150285 0.0432 0.0268" quat="0.5 0.5 -0.5 0.5" mesh="heel_btm" material="heel_btm_material" />
              <geom type="mesh" class="visual" pos="-8.36518e-05 0.0432 0.0268" quat="0.5 0.5 -0.5 0.5" mesh="toe_btm" material="toe_btm_material" />
              <geom type="mesh" class="visual" pos="2.08031e-16 0.0732 0.0268" quat="0.5 0.5 -0.5 0.5" mesh="servo_bracket_top" material="servo_bracket_top_material" />
              <geom type="mesh" class="visual" pos="-8.36518e-05 0.0433 0.0268" quat="0.5 0.5 -0.5 0.5" mesh="toe_top" material="toe_top_material" />
            </body>
          </body>
        </body>
      </body>
      <body name="upperbody" pos="1.97751e-05 4.17458e-05 0.0482" quat="0.000704463 0.707107 0.707106 0.000120096">
        <joint axis="0 0 1" name="waist_yaw" type="hinge" range="-0.523598775598297 0.5235987755983006" class="htd45hServo" />
        <inertial pos="-0.000229929 -0.000746021 -0.0939537" mass="0.222802" fullinertia="0.000980548 0.00143776 0.000544244 -2.03249e-07 -2.92739e-07 3.93304e-06" />
        <geom type="mesh" class="visual" pos="-0.000246304 -0.0003 -0.0735796" quat="1.54685e-17 -0.707107 -0.707107 -1.22231e-17" mesh="waist_platform" material="waist_platform_material" />
        <geom type="mesh" class="visual" pos="-2.56227e-19 -4.63496e-18 -0.0741796" quat="1.55835e-17 -0.707107 -0.707107 -1.21465e-17" mesh="battery_servo_connect" material="battery_servo_connect_material" />
        <geom type="mesh" class="visual" pos="-0.000246304 -0.0003 -0.0814" quat="7.22263e-17 -0.707107 0.707107 -6.87029e-17" mesh="shoulder_connect_deck" material="shoulder_connect_deck_material" />
        <geom type="mesh" class="visual" pos="-0.000246304 0.027 -0.0732" quat="0.707107 5.0581e-15 0.707107 -5.32907e-15" mesh="part_118" material="part_118_material" />
        <geom type="mesh" class="visual" pos="-4.63042e-05 -0.0003 -0.0814" quat="4.35525e-16 -0.707107 0.707107 -4.58853e-16" mesh="servo_support" material="servo_support_material" />
        <geom type="mesh" class="visual" pos="-0.000246304 -0.0003 -0.0814" quat="6.87859e-17 0.707107 0.707107 7.22516e-17" mesh="body_box" material="body_box_material" />
        <geom type="mesh" class="visual" pos="-0.000246304 -0.0003 -0.0814" quat="6.87475e-17 0.707107 0.707107 7.22132e-17" mesh="shoulder_connect_deck" material="shoulder_connect_deck_material" />
        <geom type="mesh" class="visual" pos="-0.000446304 -0.0003 -0.0814" quat="3.05989e-16 -0.707107 -0.707107 3.02524e-16" mesh="servo_support" material="servo_support_material" />
        <geom type="mesh" class="visual" pos="0.0289849 0.059345 -0.143695" quat="0.500082 -0.499918 0.499918 -0.500082" mesh="htd_45h_1circle" material="htd_45h_1circle_material" />
        <geom type="mesh" class="visual" pos="-0.000246304 -0.0003 -0.0735796" quat="1.55069e-17 -0.707107 -0.707107 -1.22231e-17" mesh="waist_platform_2" material="waist_platform_2_material" />
        <geom type="mesh" class="visual" pos="-0.000246304 0.0472 -0.0514" quat="6.87859e-17 0.707107 0.707107 7.22516e-17" mesh="hiwonderboard" material="hiwonderboard_material" />
        <geom type="mesh" class="visual" pos="0.0950037 -0.0003 -0.1282" quat="1.12757e-16 -4.46861e-15 1 9.32414e-18" mesh="bno085" material="bno085_material" />
        <geom type="mesh" class="visual" pos="-0.0294775 -0.059945 -0.143695" quat="0.500082 -0.499918 -0.499918 0.500082" mesh="htd_45h_1circle" material="htd_45h_1circle_material" />
        <body name="shoulder" pos="-0.0816463 -0.000258254 -0.13748" quat="0.500498 0.499915 0.499502 0.500085">
          <joint axis="0 0 1" name="right_shoulder_pitch" type="hinge" range="-3.1409677411758645 0.8732895384110934" class="htd45hServo" />
          <inertial pos="0.00141021 0.000108686 -0.0439491" mass="0.065" fullinertia="1.09477e-05 1.66441e-05 1.00843e-05 -4.45287e-08 5.86845e-07 5.83047e-09" />
          <geom type="mesh" class="visual" pos="3.49951e-05 0.056 0.0824" quat="0.707107 0.707107 -0.00022094 -0.00022094" mesh="shouder_connect_servo" material="shouder_connect_servo_material" />
          <geom type="mesh" class="visual" pos="-0.000314864 0.0562252 0.0813" quat="0.707107 0.707107 -0.00022094 -0.00022094" mesh="shoulder_front_ball" material="shoulder_front_ball_material" />
          <geom type="mesh" class="visual" pos="-0.000114864 0.0562251 0.0813" quat="0.707107 0.707107 -0.00022094 -0.00022094" mesh="shoulder_mid" material="shoulder_mid_material" />
          <geom type="mesh" class="visual" pos="8.51357e-05 0.056225 0.0813" quat="0.707107 0.707107 -0.00022094 -0.00022094" mesh="shoulder_back_ball" material="shoulder_back_ball_material" />
          <geom type="mesh" class="visual" pos="-0.0273605 -0.0596918 -0.047266" quat="0.500063 0.496748 0.499915 0.503252" mesh="htd_45h_1circle" material="htd_45h_1circle_material" />
        </body>
        <body name="shoulder_2" pos="0.0811537 -0.000341746 -0.13748" quat="0.500085 0.499502 -0.499915 -0.500498">
          <joint axis="0 0 1" name="left_shoulder_pitch" type="hinge" range="-0.8720498722220295 3.1422074073649284" class="htd45hServo" />
          <inertial pos="-0.0014102 -0.0001087 -0.0439491" mass="0.065" fullinertia="1.09477e-05 1.66441e-05 1.00843e-05 -4.45866e-08 -5.86845e-07 -5.83643e-09" />
          <geom type="mesh" class="visual" pos="-3.44262e-05 -0.056 0.0824" quat="0.000217348 0.000217348 0.707107 0.707107" mesh="shouder_connect_servo" material="shouder_connect_servo_material" />
          <geom type="mesh" class="visual" pos="0.000315435 -0.0562252 0.0813" quat="0.000217348 0.000217348 0.707107 0.707107" mesh="shoulder_front_ball" material="shoulder_front_ball_material" />
          <geom type="mesh" class="visual" pos="0.000115435 -0.0562251 0.0813" quat="0.000217348 0.000217348 0.707107 0.707107" mesh="shoulder_mid" material="shoulder_mid_material" />
          <geom type="mesh" class="visual" pos="-8.45645e-05 -0.056225 0.0813" quat="0.000217348 0.000217348 0.707107 0.707107" mesh="shoulder_back_ball" material="shoulder_back_ball_material" />
          <geom type="mesh" class="visual" pos="0.0273598 0.0596921 -0.047266" quat="0.503255 0.499918 -0.496745 -0.500061" mesh="htd_45h_1circle" material="htd_45h_1circle_material" />
          <body name="upper_arm" pos="-0.02447 -0.00032587 -0.0531165" quat="0.499748 -0.503833 0.500226 -0.496163">
            <joint axis="0 0 1" name="left_shoulder_roll" type="hinge" range="-2.090372598285786 0.0040225041074091195" class="htd45hServo" />
            <inertial pos="0 0 0" mass="1e-09" fullinertia="1e-09 1e-09 1e-09 0 0 0" />
            <geom type="mesh" class="visual" pos="-0.0550596 0.134822 0.0256018" quat="0.707105 0.00142293 0.707105 -0.0014134" mesh="uparm" material="uparm_material" />
            <geom type="mesh" class="visual" pos="-0.0564996 -0.135092 0.0262567" quat="0.701985 0.00432582 0.712142 0.00720485" mesh="back_ball_connector" material="back_ball_connector_material" />
            <geom type="mesh" class="visual" pos="-0.0564996 -0.135092 0.0262567" quat="0.701985 0.00432582 0.712142 0.00720485" mesh="uparm" material="uparm_material" />
            <geom type="mesh" class="visual" pos="-0.0561395 -0.134375 0.0255982" quat="0.0014134 0.707105 -0.00142293 0.707105" mesh="part_15" material="part_15_material" />
            <geom type="mesh" class="visual" pos="-0.0564996 -0.135092 0.0262567" quat="0.701985 0.00432582 0.712142 0.00720485" mesh="front_ball_connector" material="front_ball_connector_material" />
            <geom type="mesh" class="visual" pos="-0.0554581 0.134824 0.0254" quat="0.707105 0.00142217 0.707105 -0.00142217" mesh="front_ball_connector" material="front_ball_connector_material" />
            <geom type="mesh" class="visual" pos="-0.0564996 -0.135092 0.0262567" quat="0.701985 0.00432582 0.712142 0.00720485" mesh="part_15" material="part_15_material" />
            <geom type="mesh" class="visual" pos="-0.0554581 0.134824 0.0254" quat="0.707105 0.00142217 0.707105 -0.00142217" mesh="back_ball_connector" material="back_ball_connector_material" />
            <body name="shoulder_3" pos="-0.000339253 -0.269025 -0.00213843" quat="0.00718877 0.0011661 -0.99994 -0.00814717">
              <joint axis="0 0 1" name="right_shoulder_roll" type="hinge" range="-0.0017394532379382429 2.092655649155257" class="htd45hServo" />
              <inertial pos="-5.13589e-05 0.00935505 -0.0229853" mass="0.065" fullinertia="1.66445e-05 1.00748e-05 1.09569e-05 1.68872e-09 -3.59955e-09 5.79762e-07" />
              <geom type="mesh" class="visual" pos="0.0558475 0.135708 -0.0229296" quat="0.704335 0.00287166 -0.709856 -0.00288939" mesh="shouder_connect_servo" material="shouder_connect_servo_material" />
              <geom type="mesh" class="visual" pos="0.0560753 0.134611 -0.0232868" quat="0.704335 0.00287166 -0.709856 -0.00288939" mesh="shoulder_front_ball" material="shoulder_front_ball_material" />
              <geom type="mesh" class="visual" pos="0.0560737 0.134609 -0.0230868" quat="0.704335 0.00287166 -0.709856 -0.00288939" mesh="shoulder_mid" material="shoulder_mid_material" />
              <geom type="mesh" class="visual" pos="0.0560721 0.134608 -0.0228868" quat="0.704335 0.00287166 -0.709856 -0.00288939" mesh="shoulder_back_ball" material="shoulder_back_ball_material" />
              <geom type="mesh" class="visual" pos="-0.0596436 0.0062757 -0.0522108" quat="1 0.00074741 -0.00041321 3.08837e-07" mesh="htd_45h_1circle" material="htd_45h_1circle_material" />
            </body>
            <body name="fore_arm" pos="-0.169859 -0.294247 0.0252979" quat="0.498466 0.508655 -0.499437 0.49332">
              <joint axis="0 0 1" name="right_albow_pitch" type="hinge" range="0.0 2.0943951023931953" class="htd45hServo" />
              <inertial pos="-5.13589e-05 0.00935505 -0.0225853" mass="0.065" fullinertia="1.66445e-05 1.00748e-05 1.09569e-05 1.68872e-09 -3.59955e-09 5.79762e-07" />
              <geom type="mesh" class="visual" pos="-0.000159815 -0.113816 -0.161098" quat="0.000292354 0.000292013 0.707519 -0.706694" mesh="forearm" material="forearm_material" />
              <geom type="mesh" class="visual" pos="-0.0596436 0.0062757 -0.0518108" quat="1 0.00074741 -0.00041321 3.08837e-07" mesh="htd_45h_1circle" material="htd_45h_1circle_material" />
            </body>
            <body name="fore_arm_2" pos="-0.169695 -0.023419 0.0255997" quat="0.500998 0.499 -0.501005 0.498993">
              <joint axis="0 0 1" name="left_albow_pitch" type="hinge" range="0.0 2.0943951023931953" class="htd45hServo" />
              <inertial pos="-5.13589e-05 0.00935505 -0.0229853" mass="0.065" fullinertia="1.66445e-05 1.00748e-05 1.09569e-05 1.68872e-09 -3.59955e-09 5.79762e-07" />
              <geom type="mesh" class="visual" pos="-0.000159815 -0.113816 -0.161498" quat="0.000292354 0.000292013 0.707519 -0.706694" mesh="forearm" material="forearm_material" />
              <geom type="mesh" class="visual" pos="-0.0596436 0.0062757 -0.0522108" quat="1 0.00074741 -0.00041321 3.08837e-07" mesh="htd_45h_1circle" material="htd_45h_1circle_material" />
            </body>
          </body>
        </body>
      </body>
    </body>
  </worldbody>
  <asset>
    <mesh file="waist_trunk_support.stl" />
    <mesh file="hip_cover.stl" />
    <mesh file="low_leg_servo_connect.stl" />
    <mesh file="servo_bracket_top.stl" />
    <mesh file="shouder_connect_servo.stl" />
    <mesh file="hip_servo_gear.stl" />
    <mesh file="shoulder_connect_deck.stl" />
    <mesh file="part_118.stl" />
    <mesh file="bno085.stl" />
    <mesh file="knee_ball_servo_connect_2.stl" />
    <mesh file="up_leg_servo_connect.stl" />
    <mesh file="knee_ball_servo_connect_3.stl" />
    <mesh file="body_box.stl" />
    <mesh file="knee_ball_mid.stl" />
    <mesh file="toe_btm.stl" />
    <mesh file="waist_platform_2.stl" />
    <mesh file="foot_main.stl" />
    <mesh file="shoulder_back_ball.stl" />
    <mesh file="heel_btm.stl" />
    <mesh file="servo_support.stl" />
    <mesh file="shoulder_mid.stl" />
    <mesh file="hiwonderboard.stl" />
    <mesh file="knee_ball_left.stl" />
    <mesh file="back_ball_connector.stl" />
    <mesh file="heel_top.stl" />
    <mesh file="part_15.stl" />
    <mesh file="trunk_bottom.stl" />
    <mesh file="hip_servo_hook_left.stl" />
    <mesh file="scroll_inner.stl" />
    <mesh file="knee_ball_servo_connect_1.stl" />
    <mesh file="low_leg_left.stl" />
    <mesh file="hip_servo_hook_right.stl" />
    <mesh file="uparm.stl" />
    <mesh file="waist_platform.stl" />
    <mesh file="knee_ball_right.stl" />
    <mesh file="hip_gear.stl" />
    <mesh file="scroll_out.stl" />
    <mesh file="up_leg.stl" />
    <mesh file="trunk_servo_connect.stl" />
    <mesh file="icm45686.stl" />
    <mesh file="shoulder_front_ball.stl" />
    <mesh file="forearm.stl" />
    <mesh file="hip_trunk_connect.stl" />
    <mesh file="low_leg_right.stl" />
    <mesh file="htd_45h_1circle.stl" />
    <mesh file="front_ball_connector.stl" />
    <mesh file="battery_servo_connect.stl" />
    <mesh file="toe_top.stl" />
    <material name="htd_45h_1circle_material" rgba="0.615686 0.811765 0.929412 1" />
    <material name="waist_trunk_support_material" rgba="0.980392 0.713725 0.00392157 1" />
    <material name="trunk_bottom_material" rgba="0.301961 0.301961 0.301961 1" />
    <material name="trunk_servo_connect_material" rgba="0.647059 0.647059 0.647059 1" />
    <material name="hip_cover_material" rgba="0.768627 0.886275 0.952941 1" />
    <material name="scroll_out_material" rgba="0.901961 0.878431 0.811765 1" />
    <material name="hip_trunk_connect_material" rgba="0.647059 0.647059 0.647059 1" />
    <material name="scroll_inner_material" rgba="0.341176 0.776471 0.741176 1" />
    <material name="hip_servo_hook_left_material" rgba="0.972549 0.529412 0.00392157 1" />
    <material name="hip_servo_gear_material" rgba="0.980392 0.713725 0.00392157 1" />
    <material name="hip_gear_material" rgba="0.231373 0.380392 0.705882 1" />
    <material name="up_leg_servo_connect_material" rgba="0.615686 0.811765 0.929412 1" />
    <material name="up_leg_material" rgba="0.647059 0.647059 0.647059 1" />
    <material name="icm45686_material" rgba="0.301961 0.301961 0.301961 1" />
    <material name="knee_ball_left_material" rgba="0.231373 0.380392 0.705882 1" />
    <material name="knee_ball_mid_material" rgba="0.231373 0.380392 0.705882 1" />
    <material name="knee_ball_right_material" rgba="0.231373 0.380392 0.705882 1" />
    <material name="knee_ball_servo_connect_3_material" rgba="0.768627 0.886275 0.952941 1" />
    <material name="low_leg_right_material" rgba="0.498039 0.498039 0.498039 1" />
    <material name="low_leg_left_material" rgba="0.498039 0.498039 0.498039 1" />
    <material name="knee_ball_servo_connect_2_material" rgba="0.972549 0.529412 0.00392157 1" />
    <material name="low_leg_servo_connect_material" rgba="0.980392 0.713725 0.00392157 1" />
    <material name="knee_ball_servo_connect_1_material" rgba="0.917647 0.917647 0.917647 1" />
    <material name="heel_top_material" rgba="0.301961 0.301961 0.301961 1" />
    <material name="foot_main_material" rgba="0.980392 0.713725 0.00392157 1" />
    <material name="heel_btm_material" rgba="0.768627 0.886275 0.952941 1" />
    <material name="toe_btm_material" rgba="0.231373 0.380392 0.705882 1" />
    <material name="servo_bracket_top_material" rgba="0.4 0.4 0.4 1" />
    <material name="toe_top_material" rgba="0.301961 0.301961 0.301961 1" />
    <material name="hip_servo_hook_right_material" rgba="0.972549 0.529412 0.00392157 1" />
    <material name="waist_platform_material" rgba="0.231373 0.380392 0.705882 1" />
    <material name="battery_servo_connect_material" rgba="0.980392 0.713725 0.00392157 1" />
    <material name="shoulder_connect_deck_material" rgba="0.615686 0.811765 0.929412 1" />
    <material name="part_118_material" rgba="0.372549 0.654902 0.239216 1" />
    <material name="servo_support_material" rgba="0.498039 0.498039 0.498039 1" />
    <material name="body_box_material" rgba="0.768627 0.886275 0.952941 1" />
    <material name="waist_platform_2_material" rgba="0.231373 0.380392 0.705882 1" />
    <material name="hiwonderboard_material" rgba="1 0.992157 0.992157 1" />
    <material name="bno085_material" rgba="0.513725 0.415686 0.733333 1" />
    <material name="shouder_connect_servo_material" rgba="0.917647 0.917647 0.917647 1" />
    <material name="shoulder_front_ball_material" rgba="0.647059 0.647059 0.647059 1" />
    <material name="shoulder_mid_material" rgba="0.917647 0.917647 0.917647 1" />
    <material name="shoulder_back_ball_material" rgba="0.980392 0.713725 0.00392157 1" />
    <material name="uparm_material" rgba="0.917647 0.917647 0.917647 1" />
    <material name="back_ball_connector_material" rgba="0.498039 0.498039 0.498039 1" />
    <material name="part_15_material" rgba="0.615686 0.811765 0.929412 1" />
    <material name="front_ball_connector_material" rgba="0.231373 0.380392 0.705882 1" />
    <material name="forearm_material" rgba="0.768627 0.886275 0.952941 1" />
  </asset>
  <actuator>
    <position class="htd45hServo" name="left_hip_pitch" joint="left_hip_pitch" inheritrange="1" />
    <position class="htd45hServo" name="left_hip_roll" joint="left_hip_roll" inheritrange="1" />
    <position class="htd45hServo" name="left_knee_pitch" joint="left_knee_pitch" inheritrange="1" />
    <position class="htd45hServo" name="left_ankle_pitch" joint="left_ankle_pitch" inheritrange="1" />
    <position class="htd45hServo" name="right_hip_pitch" joint="right_hip_pitch" inheritrange="1" />
    <position class="htd45hServo" name="right_hip_roll" joint="right_hip_roll" inheritrange="1" />
    <position class="htd45hServo" name="right_knee_pitch" joint="right_knee_pitch" inheritrange="1" />
    <position class="htd45hServo" name="right_ankle_pitch" joint="right_ankle_pitch" inheritrange="1" />
    <position class="htd45hServo" name="waist_yaw" joint="waist_yaw" inheritrange="1" />
    <position class="htd45hServo" name="right_shoulder_pitch" joint="right_shoulder_pitch" inheritrange="1" />
    <position class="htd45hServo" name="left_shoulder_pitch" joint="left_shoulder_pitch" inheritrange="1" />
    <position class="htd45hServo" name="left_shoulder_roll" joint="left_shoulder_roll" inheritrange="1" />
    <position class="htd45hServo" name="right_shoulder_roll" joint="right_shoulder_roll" inheritrange="1" />
    <position class="htd45hServo" name="right_albow_pitch" joint="right_albow_pitch" inheritrange="1" />
    <position class="htd45hServo" name="left_albow_pitch" joint="left_albow_pitch" inheritrange="1" />
  </actuator>
  <equality />
</mujoco>