<mujoco model="WildRobotDev">
  <option>
    <flag eulerdamp="disable" />
  </option>
  <compiler angle="radian" meshdir="assets" autolimits="true" />
  <default>
    <default class="WildRobotDev">
      <joint frictionloss="0.1" armature="0.005" />
      <position kp="50" dampratio="1" />
      <default class="visual">
        <geom type="mesh" contype="0" conaffinity="0" group="2" />
      </default>
      <default class="collision">
        <geom group="3" />
      </default>
    </default>
  </default>
  <sensor>
    <gyro site="chest_imu" name="chest_imu_gyro" noise="0.0002" cutoff="100" />
    <accelerometer site="chest_imu" name="chest_imu_accel" noise="0.0015" cutoff="100" />
    <magnetometer site="chest_imu" name="chest_imu_mag" noise="0.3" />
    <framequat objtype="site" objname="chest_imu" name="chest_imu_quat" />
    <gyro site="left_knee_imu" name="left_knee_imu_gyro" noise="0.00005" cutoff="200" />
    <accelerometer site="left_knee_imu" name="left_knee_imu_accel" noise="0.0008" cutoff="200" />
    <gyro site="right_knee_imu" name="right_knee_imu_gyro" noise="0.00005" cutoff="200" />
    <accelerometer site="right_knee_imu" name="right_knee_imu_accel" noise="0.0008" cutoff="200" />
    <gyro site="pelvis_mimic" name="pelvis_gyro" />
    <accelerometer site="pelvis_mimic" name="pelvis_accel" />
    <velocimeter site="pelvis_mimic" name="pelvis_local_linvel" />
    <framequat objtype="site" objname="pelvis_mimic" name="pelvis_quat" />
    <framezaxis objtype="site" objname="pelvis_mimic" name="pelvis_upvector" />
    <framexaxis objtype="site" objname="pelvis_mimic" name="pelvis_forwardvector" />
    <framelinvel objtype="site" objname="pelvis_mimic" name="pelvis_global_linvel" />
    <frameangvel objtype="site" objname="pelvis_mimic" name="pelvis_global_angvel" />
    <gyro site="right_hip_mimic" name="right_hip_gyro" />
    <accelerometer site="right_hip_mimic" name="right_hip_accel" />
    <framequat objtype="site" objname="right_hip_mimic" name="right_hip_quat" />
    <frameangvel objtype="site" objname="right_hip_mimic" name="right_hip_angvel" />
    <gyro site="right_knee_mimic" name="right_knee_gyro" />
    <accelerometer site="right_knee_mimic" name="right_knee_accel" />
    <framequat objtype="site" objname="right_knee_mimic" name="right_knee_quat" />
    <framelinvel objtype="site" objname="right_knee_mimic" name="right_knee_linvel" />
    <gyro site="right_foot_mimic" name="right_foot_gyro" />
    <accelerometer site="right_foot_mimic" name="right_foot_accel" />
    <framequat objtype="site" objname="right_foot_mimic" name="right_foot_quat" />
    <framelinvel objtype="site" objname="right_foot_mimic" name="right_foot_linvel" />
    <framezaxis objtype="site" objname="right_foot_mimic" name="right_foot_upvector" />
    <gyro site="left_hip_mimic" name="left_hip_gyro" />
    <accelerometer site="left_hip_mimic" name="left_hip_accel" />
    <framequat objtype="site" objname="left_hip_mimic" name="left_hip_quat" />
    <frameangvel objtype="site" objname="left_hip_mimic" name="left_hip_angvel" />
    <gyro site="left_knee_mimic" name="left_knee_gyro" />
    <accelerometer site="left_knee_mimic" name="left_knee_accel" />
    <framequat objtype="site" objname="left_knee_mimic" name="left_knee_quat" />
    <framelinvel objtype="site" objname="left_knee_mimic" name="left_knee_linvel" />
    <gyro site="left_foot_mimic" name="left_foot_gyro" />
    <accelerometer site="left_foot_mimic" name="left_foot_accel" />
    <framequat objtype="site" objname="left_foot_mimic" name="left_foot_quat" />
    <framelinvel objtype="site" objname="left_foot_mimic" name="left_foot_linvel" />
    <framezaxis objtype="site" objname="left_foot_mimic" name="left_foot_upvector" />
  </sensor>
  <default>
    <default class="htd45hServo">
      <geom contype="0" conaffinity="0" />
      <joint damping="0.08516" frictionloss="0.022275" armature="0.024992" />
      <position kp="21.1" kv="0.5" forcerange="-4.0 4.0" />
    </default>
    <default class="backlash">
      <joint damping="0.01" frictionloss="0" armature="0.01" limited="true" range="-0.008726646259971648 0.008726646259971648" />
    </default>
  </default>
  <worldbody>
    <body name="waist" pos="0 0 0.5" quat="1 0 0 0" childclass="WildRobotDev">
      <freejoint name="waist_freejoint" />
      <inertial pos="-0.00181517 -3.08835e-05 0.00596571" mass="0.439621" fullinertia="0.000998265 0.000698685 0.00070313 -7.22885e-08 1.38528e-05 5.24148e-07" />
      <geom type="mesh" class="visual" pos="-0.0596393 -0.00143119 -0.0273687" quat="0.706991 0.707223 -0 2.16453e-17" mesh="htd_45h_1circle" material="htd_45h_1circle_material" />
      <geom type="mesh" class="visual" pos="0.000128558 -0.000153209 0.12518" quat="0.34202 -1.65887e-17 -5.55112e-17 -0.939693" mesh="waist_trunk_support" material="waist_trunk_support_material" />
      <geom type="mesh" class="visual" pos="-1.8982e-19 0 0" quat="0.707107 0 0 -0.707107" mesh="trunk_bottom" material="trunk_bottom_material" />
      <geom type="mesh" class="visual" pos="-0.00619509 -0.059645 -0.00396881" quat="0.707107 0.000116219 0.000116219 0.707107" mesh="htd_45h_1circle" material="htd_45h_1circle_material" />
      <geom type="mesh" class="visual" pos="5.89806e-17 -3.1225e-17 0" quat="0.707107 0 0 -0.707107" mesh="trunk_servo_connect" material="trunk_servo_connect_material" />
      <geom type="mesh" class="visual" pos="1.38778e-17 -0.00025 1.47949e-17" quat="0.707107 0 0 0.707107" mesh="hip_cover" material="hip_cover_material" />
      <geom type="mesh" class="visual" pos="-1.59595e-16 -1.66533e-16 0.12518" quat="0.34202 -5.80156e-17 0 -0.939693" mesh="scroll_out" material="scroll_out_material" />
      <geom type="mesh" class="visual" pos="0.000128558 0.000153209 0.12518" quat="0.939693 -2.94205e-17 -1.35637e-16 -0.34202" mesh="waist_trunk_support" material="waist_trunk_support_material" />
      <geom type="mesh" class="visual" pos="1.38778e-17 -0.0001 1.53661e-17" quat="0.707107 0 1.11022e-16 0.707107" mesh="hip_trunk_connect" material="hip_trunk_connect_material" />
      <geom type="mesh" class="visual" pos="-0.000128558 -0.000153209 0.12518" quat="0.34202 -0 -5.91646e-31 0.939693" mesh="waist_trunk_support" material="waist_trunk_support_material" />
      <geom type="mesh" class="visual" pos="-0.000128558 0.000153209 0.12518" quat="0.939693 0 -0 0.34202" mesh="waist_trunk_support" material="waist_trunk_support_material" />
      <geom type="mesh" class="visual" pos="-1.38778e-17 0.00025 1.46954e-17" quat="0.707107 0 2.22045e-16 -0.707107" mesh="hip_cover" material="hip_cover_material" />
      <geom type="mesh" class="visual" pos="0.0596393 0.00143119 -0.0273687" quat="2.16453e-17 0 -0.707223 -0.706991" mesh="htd_45h_1circle" material="htd_45h_1circle_material" />
      <geom type="mesh" class="visual" pos="-1.38778e-17 0.0001 1.3452e-17" quat="0.707107 0 1.11022e-16 -0.707107" mesh="hip_trunk_connect" material="hip_trunk_connect_material" />
      <site group="3" name="pelvis_mimic" pos="0 0 0" quat="1 0 0 0" />
      <body name="right_hip" pos="4.74705e-05 -0.0536 -0.0335836" quat="0.706694 -0.707519 -0.000292013 0.000292354">
        <joint axis="0 0 1" name="right_hip_pitch" type="hinge" range="-1.5707963267948957 0.08726646259971736" class="htd45hServo" />
        <inertial pos="0.00272374 -0.00897832 -0.0331404" mass="0.0849728" fullinertia="2.00434e-05 1.92798e-05 2.44237e-05 -3.96751e-07 7.91944e-07 -1.48675e-06" />
        <geom type="mesh" class="visual" pos="-0.0254688 -0.0063813 -0.0961393" quat="0.000116219 -0.707107 -0.000116219 -0.707107" mesh="htd_45h_1circle" material="htd_45h_1circle_material" />
        <geom type="mesh" class="visual" pos="-0.0001 -0.03359 0.0566" quat="0.5 0.5 -0.5 0.5" mesh="hip_servo_hook_right" material="hip_servo_hook_right_material" />
        <site group="3" name="right_hip_mimic" pos="-0.000628163 -9.99278e-05 -0.0365495" quat="0.707102 0.707102 0.00246826 0.00246826" />
        <body name="upper_leg" pos="0.0267 -0.000166429 -0.0364525" quat="0.706814 -0.00041245 -0.707399 -0.000412109">
          <joint axis="0 0 1" name="right_hip_roll" type="hinge" range="-0.17453292519943206 1.5707963267948974" class="htd45hServo" />
          <inertial pos="-0.00104181 0.159312 0.0267034" mass="0.236565" fullinertia="0.000987068 0.000125887 0.000979617 9.86461e-06 9.63535e-09 1.07533e-06" />
          <geom type="mesh" class="visual" pos="-0.095 -2.08167e-17 0.0267" quat="0.707107 0.707107 1.11022e-16 3.86731e-17" mesh="up_leg_servo_connect" material="up_leg_servo_connect_material" />
          <geom type="mesh" class="visual" pos="-4.02456e-16 0.174352 0.1872" quat="0.5 0.5 0.5 -0.5" mesh="icm45686" material="icm45686_material" />
          <geom type="mesh" class="visual" pos="-0.0948 -0.0004 0.0266985" quat="0.707105 0.707109 -2.84803e-06 2.84595e-06" mesh="knee_ball_left" material="knee_ball_left_material" />
          <geom type="mesh" class="visual" pos="-0.095 -0.0002 0.0267" quat="0.707107 0.707107 7.77156e-16 3.66896e-16" mesh="knee_ball_mid" material="knee_ball_mid_material" />
          <geom type="mesh" class="visual" pos="-0.095 1.38778e-16 0.0267" quat="0.707107 0.707107 0 -7.3325e-17" mesh="up_leg" material="up_leg_material" />
          <geom type="mesh" class="visual" pos="0.0253613 0.198628 -0.0329432" quat="0.706811 0.000530114 -0.707402 0.000526879" mesh="htd_45h_1circle" material="htd_45h_1circle_material" />
          <geom type="mesh" class="visual" pos="-0.0952 -0.000399963 0.0268019" quat="0.707365 0.706849 -2.31378e-05 2.31379e-05" mesh="knee_ball_right" material="knee_ball_right_material" />
          <site group="3" name="right_knee_mimic" pos="0.000338462 0.192501 0.0266257" quat="0.498751 0.501662 0.498337 -0.501241" />
          <site group="3" name="right_knee_imu" pos="-3.33067e-16 0.173352 0.0264651" quat="0.5 0.5 0.5 -0.5" />
          <body name="lower_leg" pos="-0.02685 0.192352 0.0267" quat="1.83705e-06 -0.707104 1.83913e-06 -0.70711">
            <joint axis="0 0 1" name="right_knee_pitch" type="hinge" range="0.0 1.3962634015954636" class="htd45hServo" />
            <inertial pos="-0.000521354 -0.101401 0.0270617" mass="0.380663" fullinertia="0.00177714 0.000669988 0.00168908 1.88914e-05 3.0835e-08 -3.5834e-05" />
            <geom type="mesh" class="visual" pos="-2.5975e-15 0.192752 -0.0677579" quat="0.5 -0.5 -0.5 -0.5" mesh="low_leg_right" material="low_leg_right_material" />
            <geom type="mesh" class="visual" pos="-5.69437e-16 0.192752 -0.0677579" quat="0.5 -0.5 -0.5 -0.5" mesh="low_leg_left" material="low_leg_left_material" />
            <geom type="mesh" class="visual" pos="0.0596393 -0.173769 0.0526109" quat="9.4369e-15 2.62544e-15 -1 0.000164358" mesh="htd_45h_1circle" material="htd_45h_1circle_material" />
            <body name="right_ankle" pos="-4.74705e-05 -0.179984 0.000442075" quat="2.40923e-07 -0.00041321 0.000583051 -1">
              <joint axis="0 0 1" name="right_ankle_pitch" type="hinge" range="-0.5235987755983201 0.5235987755982775" class="htd45hServo" />
              <inertial pos="-0.000778386 0.0291765 0.0259275" mass="0.0230191" fullinertia="1.34186e-05 1.32703e-05 1.41853e-05 1.80568e-07 1.56329e-08 -2.24395e-07" />
              <geom type="mesh" class="visual" pos="-1.00137e-15 0.0722 0.0268" quat="0.5 0.5 0.5 -0.5" mesh="servo_bracket_btm" material="servo_bracket_btm_material" />
              <geom type="mesh" class="visual" pos="-1.12407e-15 0.0732 0.0268" quat="0.5 0.5 -0.5 0.5" mesh="servo_bracket_top" material="servo_bracket_top_material" />
              <body name="right_foot" pos="-0.0268 0.0594 0.0268" quat="0.5 0.5 -0.5 -0.5">
                <joint axis="0 0 1" name="right_foot_roll" type="hinge" range="-0.3490658503988375 0.3490658503988943" class="htd45hServo" />
                <inertial pos="-0.0182605 0.00187575 -0.0419443" mass="0.413618" fullinertia="0.000978456 0.000752203 0.000319832 -1.71895e-05 -3.90028e-05 -1.62365e-05" />
                <geom type="mesh" class="visual" pos="-0.0128256 0.159815 -0.0265243" quat="0.499915 0.500085 0.499502 0.500498" mesh="foot_main_right" material="foot_main_right_material" />
                <geom type="mesh" class="visual" pos="-0.0125255 -0.00118539 -0.0266289" quat="0.499915 0.500085 0.499502 0.500498" mesh="foot_btm_front" material="foot_btm_front_material" />
                <geom type="mesh" class="collision" pos="-0.0125255 -0.00118539 -0.0266289" quat="0.499915 0.500085 0.499502 0.500498" mesh="foot_btm_front" material="foot_btm_front_material" name="right_foot_btm_front" />
                <geom type="mesh" class="visual" pos="-0.0128256 0.159815 -0.0265243" quat="0.499915 0.500085 0.499502 0.500498" mesh="foot_side_right" material="foot_side_right_material" />
                <geom type="mesh" class="visual" pos="-0.0128254 -0.000185294 -0.0267108" quat="0.500498 -0.499502 0.500085 -0.499915" mesh="btm_servo_support" material="btm_servo_support_material" />
                <geom type="mesh" class="visual" pos="-0.0105255 -0.00118539 -0.0266273" quat="0.499915 0.500085 0.499502 0.500498" mesh="foot_btm_back" material="foot_btm_back_material" />
                <geom type="mesh" class="collision" pos="-0.0105255 -0.00118539 -0.0266273" quat="0.499915 0.500085 0.499502 0.500498" mesh="foot_btm_back" material="foot_btm_back_material" name="right_foot_btm_back" />
                <geom type="mesh" class="visual" pos="-0.0596436 0.0062757 -0.0522108" quat="1 0.00074741 -0.00041321 3.08837e-07" mesh="htd_45h_1circle" material="htd_45h_1circle_material" />
                <site group="3" name="right_foot_mimic" pos="-0.0294117 0.00930168 -0.0432369" quat="0.707399 0.000412109 0.706814 0.00041245" />
              </body>
            </body>
          </body>
        </body>
      </body>
      <body name="left_hip" pos="-4.74705e-05 0.0536 -0.0335836" quat="0.000292354 -0.000292013 0.707519 -0.706694">
        <joint axis="0 0 1" name="left_hip_pitch" type="hinge" range="-0.08726646259971647 1.5707963267948966" class="htd45hServo" />
        <inertial pos="-0.00291444 -0.00897832 -0.0331054" mass="0.0849728" fullinertia="2.00234e-05 1.92641e-05 2.44282e-05 3.89652e-07 -8.26001e-07 -1.4809e-06" />
        <geom type="mesh" class="visual" pos="-0.0001 -0.03359 0.0566" quat="0.5 0.5 0.5 -0.5" mesh="hip_servo_hook_left" material="hip_servo_hook_left_material" />
        <geom type="mesh" class="visual" pos="0.0252688 -0.0063813 0.0231393" quat="0.000116219 -0.707107 0.000116219 0.707107" mesh="htd_45h_1circle" material="htd_45h_1circle_material" />
        <site group="3" name="left_hip_mimic" pos="0.000428163 -9.99278e-05 -0.0364505" quat="0.00246826 -0.00246826 -0.707102 0.707102" />
        <body name="upper_leg_2" pos="-0.0269 -0.000166429 -0.0365475" quat="0.707399 -0.000412109 0.706814 0.00041245">
          <joint axis="0 0 1" name="left_hip_roll" type="hinge" range="-1.5707963267948966 0.17453292519943295" class="htd45hServo" />
          <inertial pos="-0.00104181 0.159312 0.0267034" mass="0.236565" fullinertia="0.000987068 0.000125887 0.000979617 9.86461e-06 9.63535e-09 1.07533e-06" />
          <geom type="mesh" class="visual" pos="-0.095 6.93889e-18 0.0267" quat="0.707107 0.707107 0 -2.15551e-19" mesh="up_leg_servo_connect" material="up_leg_servo_connect_material" />
          <geom type="mesh" class="visual" pos="5.55112e-17 0.174352 0.1872" quat="0.5 0.5 0.5 -0.5" mesh="icm45686" material="icm45686_material" />
          <geom type="mesh" class="visual" pos="-0.0948 -0.0004 0.0266985" quat="0.707105 0.707109 -2.84803e-06 2.84595e-06" mesh="knee_ball_left" material="knee_ball_left_material" />
          <geom type="mesh" class="visual" pos="-0.095 -0.0002 0.0267" quat="0.707107 0.707107 -1.11022e-16 1.05314e-16" mesh="knee_ball_mid" material="knee_ball_mid_material" />
          <geom type="mesh" class="visual" pos="-0.095 1.38778e-17 0.0267" quat="0.707107 0.707107 0 6.36741e-17" mesh="up_leg" material="up_leg_material" />
          <geom type="mesh" class="visual" pos="0.0253613 0.198628 -0.0329432" quat="0.706811 0.000530114 -0.707402 0.000526879" mesh="htd_45h_1circle" material="htd_45h_1circle_material" />
          <geom type="mesh" class="visual" pos="-0.0952 -0.000399963 0.0268019" quat="0.707365 0.706849 -2.31378e-05 2.31379e-05" mesh="knee_ball_right" material="knee_ball_right_material" />
          <site group="3" name="left_knee_mimic" pos="0.000338462 0.192501 0.0266257" quat="0.498751 0.501662 0.498337 -0.501241" />
          <site group="3" name="left_knee_imu" pos="1.11022e-16 0.173352 0.0264651" quat="0.5 0.5 0.5 -0.5" />
          <body name="lower_leg_2" pos="-0.02685 0.192352 0.0267" quat="1.83705e-06 -0.707104 1.83913e-06 -0.70711">
            <joint axis="0 0 1" name="left_knee_pitch" type="hinge" range="0.0 1.3962634015954636" class="htd45hServo" />
            <inertial pos="-0.000521354 -0.101401 0.0270617" mass="0.380663" fullinertia="0.00177714 0.000669988 0.00168908 1.88914e-05 3.0835e-08 -3.5834e-05" />
            <geom type="mesh" class="visual" pos="-2.21559e-15 0.192752 -0.0677579" quat="0.5 -0.5 -0.5 -0.5" mesh="low_leg_right" material="low_leg_right_material" />
            <geom type="mesh" class="visual" pos="-2.87964e-16 0.192752 -0.0677579" quat="0.5 -0.5 -0.5 -0.5" mesh="low_leg_left" material="low_leg_left_material" />
            <geom type="mesh" class="visual" pos="0.0596393 -0.173769 0.0526109" quat="1.05471e-14 1.04263e-16 -1 0.000164358" mesh="htd_45h_1circle" material="htd_45h_1circle_material" />
            <body name="left_ankle" pos="-4.74705e-05 -0.179984 0.000442075" quat="2.40923e-07 -0.00041321 0.000583051 -1">
              <joint axis="0 0 1" name="left_ankle_pitch" type="hinge" range="-0.5235987755982988 0.5235987755982988" class="htd45hServo" />
              <inertial pos="0.000778386 0.0291765 0.0259275" mass="0.0230191" fullinertia="1.34186e-05 1.32703e-05 1.41853e-05 -1.80568e-07 -1.56329e-08 -2.24395e-07" />
              <geom type="mesh" class="visual" pos="-1.13299e-17 0.0722 0.0268" quat="0.5 0.5 -0.5 0.5" mesh="servo_bracket_btm" material="servo_bracket_btm_material" />
              <geom type="mesh" class="visual" pos="-4.77049e-18 0.0732 0.0268" quat="0.5 0.5 -0.5 0.5" mesh="servo_bracket_top" material="servo_bracket_top_material" />
              <body name="left_foot" pos="0.0268 0.0594 0.0268" quat="0.5 -0.5 0.5 -0.5">
                <joint axis="0 0 1" name="left_foot_roll" type="hinge" range="-0.3490658503988659 0.3490658503988659" class="htd45hServo" />
                <inertial pos="-0.0183724 0.00183883 -0.0102858" mass="0.413618" fullinertia="0.00096407 0.00073874 0.0003209 -1.74031e-05 2.95872e-05 1.47775e-05" />
                <geom type="mesh" class="visual" pos="-0.0128254 -0.000185294 -0.0267108" quat="0.500498 -0.499502 0.500085 -0.499915" mesh="btm_servo_support" material="btm_servo_support_material" />
                <geom type="mesh" class="visual" pos="-0.0596436 0.0062757 -0.0522108" quat="1 0.00074741 -0.00041321 3.08837e-07" mesh="htd_45h_1circle" material="htd_45h_1circle_material" />
                <geom type="mesh" class="visual" pos="-0.0125253 -0.0011852 -0.0267946" quat="0.500498 -0.499502 0.500085 -0.499915" mesh="foot_btm_back" material="foot_btm_back_material" />
                <geom type="mesh" class="collision" pos="-0.0125253 -0.0011852 -0.0267946" quat="0.500498 -0.499502 0.500085 -0.499915" mesh="foot_btm_back" material="foot_btm_back_material" name="left_foot_btm_back" />
                <geom type="mesh" class="visual" pos="-0.0128254 -0.000185294 -0.0267108" quat="0.500498 -0.499502 0.500085 -0.499915" mesh="foot_side" material="foot_side_material" />
                <geom type="mesh" class="visual" pos="-0.0128254 -0.000185294 -0.0267108" quat="0.500498 -0.499502 0.500085 -0.499915" mesh="foot_main" material="foot_main_material" />
                <geom type="mesh" class="visual" pos="-0.0125255 -0.00118539 -0.0266289" quat="0.500498 -0.499502 0.500085 -0.499915" mesh="foot_btm_front" material="foot_btm_front_material" />
                <geom type="mesh" class="collision" pos="-0.0125255 -0.00118539 -0.0266289" quat="0.500498 -0.499502 0.500085 -0.499915" mesh="foot_btm_front" material="foot_btm_front_material" name="left_foot_btm_front" />
                <site group="3" name="left_foot_mimic" pos="-0.0294391 0.00926314 -0.0101901" quat="0.00041245 -0.706814 0.000412109 -0.707399" />
              </body>
            </body>
          </body>
        </body>
      </body>
      <body name="chassis" pos="1.97751e-05 4.17458e-05 0.0482" quat="0.000704463 0.707107 0.707106 0.000120096">
        <joint axis="0 0 1" name="waist_yaw" type="hinge" range="-0.5235987755982606 0.523598775598337" class="htd45hServo" />
        <inertial pos="0.00235226 0.00416672 -0.0682563" mass="0.841214" fullinertia="0.00126289 0.00149567 0.000913668 -0.000107674 2.45804e-05 3.30802e-05" />
        <geom type="mesh" class="visual" pos="0.0233086 -0.211191 -0.0331" quat="0.707107 0.707107 -2.02061e-14 -2.04114e-14" mesh="cell" material="cell_material" />
        <geom type="mesh" class="visual" pos="0.00985858 0.0311486 -0.068" quat="1 1.19943e-17 5.55112e-17 -2.55934e-14" mesh="rp_assemble" material="rp_assemble_material" />
        <geom type="mesh" class="visual" pos="-0.000141421 0.0233586 -0.068" quat="9.55702e-17 -2.56973e-14 -1 -1.31265e-17" mesh="batterybox" material="batterybox_material" />
        <geom type="mesh" class="visual" pos="0.0951086 -0.000141421 -0.119" quat="2.46218e-14 -7.29164e-17 -0 1" mesh="bno085" material="bno085_material" />
        <geom type="mesh" class="visual" pos="-0.000141421 -0.234991 -0.0331" quat="0.707107 0.707107 -2.02061e-14 -2.04114e-14" mesh="cell" material="cell_material" />
        <geom type="mesh" class="visual" pos="-0.0235914 -0.234991 -0.0331" quat="0.707107 0.707107 -2.02061e-14 -2.04114e-14" mesh="cell" material="cell_material" />
        <geom type="mesh" class="visual" pos="-0.000141421 -0.000141421 -0.0763796" quat="3.36128e-18 1 -2.28694e-14 -1.00215e-17" mesh="waist_platform" material="waist_platform_material" />
        <geom type="mesh" class="visual" pos="-0.000141421 -0.000141421 -0.0763796" quat="1.18927e-16 1 -2.5683e-14 -6.20414e-17" mesh="waist_platform_2" material="waist_platform_2_material" />
        <geom type="mesh" class="visual" pos="0.0233086 -0.234991 -0.0331" quat="0.707107 0.707107 -2.02061e-14 -2.04114e-14" mesh="cell" material="cell_material" />
        <geom type="mesh" class="visual" pos="-0.0235914 -0.211191 -0.0331" quat="0.707107 0.707107 -2.02061e-14 -2.04114e-14" mesh="cell" material="cell_material" />
        <geom type="mesh" class="visual" pos="-0.000141421 -0.211191 -0.0331" quat="0.707107 0.707107 -2.02061e-14 -2.04114e-14" mesh="cell" material="cell_material" />
        <site group="3" name="chest_imu" pos="0.000119839 -0.000141421 -0.119" quat="3.14602e-17 0.707107 0.707107 7.73198e-17" />
      </body>
    </body>
  </worldbody>
  <asset>
    <mesh file="batterybox.stl" />
    <mesh file="rp_assemble.stl" />
    <mesh file="foot_main.stl" />
    <mesh file="htd_45h_1circle.stl" />
    <mesh file="foot_btm_front.stl" />
    <mesh file="cell.stl" />
    <mesh file="low_leg_right.stl" />
    <mesh file="btm_servo_support.stl" />
    <mesh file="foot_side.stl" />
    <mesh file="scroll_out.stl" />
    <mesh file="hip_trunk_connect.stl" />
    <mesh file="knee_ball_mid.stl" />
    <mesh file="bno085.stl" />
    <mesh file="hip_servo_hook_left.stl" />
    <mesh file="trunk_bottom.stl" />
    <mesh file="waist_platform_2.stl" />
    <mesh file="trunk_servo_connect.stl" />
    <mesh file="servo_bracket_top.stl" />
    <mesh file="knee_ball_right.stl" />
    <mesh file="low_leg_left.stl" />
    <mesh file="waist_trunk_support.stl" />
    <mesh file="foot_side_right.stl" />
    <mesh file="hip_servo_hook_right.stl" />
    <mesh file="waist_platform.stl" />
    <mesh file="icm45686.stl" />
    <mesh file="up_leg_servo_connect.stl" />
    <mesh file="hip_cover.stl" />
    <mesh file="foot_btm_back.stl" />
    <mesh file="knee_ball_left.stl" />
    <mesh file="servo_bracket_btm.stl" />
    <mesh file="foot_main_right.stl" />
    <mesh file="up_leg.stl" />
    <material name="htd_45h_1circle_material" rgba="0.615686 0.811765 0.929412 1" />
    <material name="waist_trunk_support_material" rgba="0.980392 0.713725 0.00392157 1" />
    <material name="trunk_bottom_material" rgba="0.301961 0.301961 0.301961 1" />
    <material name="trunk_servo_connect_material" rgba="0.647059 0.647059 0.647059 1" />
    <material name="hip_cover_material" rgba="0.768627 0.886275 0.952941 1" />
    <material name="scroll_out_material" rgba="0.901961 0.878431 0.811765 1" />
    <material name="hip_trunk_connect_material" rgba="0.647059 0.647059 0.647059 1" />
    <material name="hip_servo_hook_right_material" rgba="0.972549 0.529412 0.00392157 1" />
    <material name="up_leg_servo_connect_material" rgba="0.615686 0.811765 0.929412 1" />
    <material name="icm45686_material" rgba="0.301961 0.301961 0.301961 1" />
    <material name="knee_ball_left_material" rgba="0.231373 0.380392 0.705882 1" />
    <material name="knee_ball_mid_material" rgba="0.231373 0.380392 0.705882 1" />
    <material name="up_leg_material" rgba="0.647059 0.647059 0.647059 1" />
    <material name="knee_ball_right_material" rgba="0.231373 0.380392 0.705882 1" />
    <material name="low_leg_right_material" rgba="0.498039 0.498039 0.498039 1" />
    <material name="low_leg_left_material" rgba="0.498039 0.498039 0.498039 1" />
    <material name="servo_bracket_btm_material" rgba="0.498039 0.498039 0.498039 1" />
    <material name="servo_bracket_top_material" rgba="0.980392 0.713725 0.00392157 1" />
    <material name="foot_main_right_material" rgba="0.980392 0.713725 0.00392157 1" />
    <material name="foot_btm_front_material" rgba="0.231373 0.380392 0.705882 1" />
    <material name="foot_side_right_material" rgba="0.980392 0.713725 0.00392157 1" />
    <material name="btm_servo_support_material" rgba="0.972549 0.529412 0.00392157 1" />
    <material name="foot_btm_back_material" rgba="0.768627 0.886275 0.952941 1" />
    <material name="hip_servo_hook_left_material" rgba="0.972549 0.529412 0.00392157 1" />
    <material name="foot_side_material" rgba="0.980392 0.713725 0.00392157 1" />
    <material name="foot_main_material" rgba="0.980392 0.713725 0.00392157 1" />
    <material name="cell_material" rgba="0.980392 0.713725 0.00392157 1" />
    <material name="rp_assemble_material" rgba="0.513725 0.737255 0.407843 1" />
    <material name="batterybox_material" rgba="0.301961 0.301961 0.301961 1" />
    <material name="bno085_material" rgba="0.513725 0.415686 0.733333 1" />
    <material name="waist_platform_material" rgba="0.231373 0.380392 0.705882 1" />
    <material name="waist_platform_2_material" rgba="0.231373 0.380392 0.705882 1" />
  </asset>
  <actuator>
    <position class="htd45hServo" name="right_hip_pitch" joint="right_hip_pitch" inheritrange="1" />
    <position class="htd45hServo" name="right_hip_roll" joint="right_hip_roll" inheritrange="1" />
    <position class="htd45hServo" name="right_knee_pitch" joint="right_knee_pitch" inheritrange="1" />
    <position class="htd45hServo" name="right_ankle_pitch" joint="right_ankle_pitch" inheritrange="1" />
    <position class="htd45hServo" name="right_foot_roll" joint="right_foot_roll" inheritrange="1" />
    <position class="htd45hServo" name="left_hip_pitch" joint="left_hip_pitch" inheritrange="1" />
    <position class="htd45hServo" name="left_hip_roll" joint="left_hip_roll" inheritrange="1" />
    <position class="htd45hServo" name="left_knee_pitch" joint="left_knee_pitch" inheritrange="1" />
    <position class="htd45hServo" name="left_ankle_pitch" joint="left_ankle_pitch" inheritrange="1" />
    <position class="htd45hServo" name="left_foot_roll" joint="left_foot_roll" inheritrange="1" />
    <position class="htd45hServo" name="waist_yaw" joint="waist_yaw" inheritrange="1" />
  </actuator>
  <equality />
</mujoco>